Workbook

Sheet README
A1: Autumn Harvest Festival 2026: Vendor Booth Mix Optimization
A2: WDPR 2026 IE Case Study, Part 2. Built in 2026. Companion to festival_forecast_model.xlsx (Part 1).
A4: Purpose | B4: Recommend the number of Food & Beverage, Merchandise, and Activities & Experiences booths within 120 standard booth equivalents, balancing revenue, guest experience (queue time), variety, and operational feasibility.
A5: Method | B5: Three layers. (1) Demand and throughput: the Part 1 expected peak day (10,808 guests) is converted to transactions per hour by category, and Little's Law plus a per-booth M/M/1 queue give the minimum booths needed to hold peak utilization at or below 85%. (2) Integer program by exhaustive enumeration: every feasible (F, M, A) mix with F + M + 2A = 120 is evaluated on contribution margin, subject to service-level, variety, and feasibility constraints; the best is selected. (3) Stress test of the chosen mix under the Low and High peak days from Part 1.
A6: Why not pure revenue maximization | B6: Per space, F&B earns roughly 3.4x Merchandise and 7x Activities. A revenue-only rule fills the grounds with food, starves the family activities that define the festival, and ignores that guests who stay longer buy more food. The model therefore treats Activities as a complement to F&B (dwell effect) and imposes variety floors and an Activities ceiling as explicit, editable constraints.
A7: Revenue metric | B7: The case does not say how the festival earns from booths. This model uses vendor contribution margin (gross sales minus operating cost at the case's High / Medium / Low-Medium tiers). If leadership confirms a commission or rent model, set the commission rate on Inputs and read festival revenue on Recommendation.
A8: Sheet guide | B8: Inputs: every parameter with source. Demand: transactions, peak-hour rates, minimum booths per category and scenario. Optimizer: the enumeration grid (do not edit; formulas only). Recommendation: chosen mix, metrics, alternatives, stress test, optional 2025 delta. Summary: dashboard and charts.
A9: Color legend | B9: Blue text = editable input. Black = formula. Green = link to another sheet. Yellow fill = key assumption. Change inputs only on the Inputs sheet.

Sheet Summary
A1: Summary dashboard: recommended 2026 booth mix
A2: Method: Little's Law and per-booth M/M/1 queues set minimum capacity; an exhaustive-enumeration integer program picks the contribution-maximizing mix within service-level, variety, and feasibility constraints; stress-tested on Part 1 scenarios.
A4: Category | B4: Booths | C4: Space equivalents | D4: Share of space | E4: Design-day contribution ($)
A5: Food & Beverage | B5: =Recommendation!B8 -> 45 | C5: =Recommendation!D8 -> 45 | D5: =Recommendation!E8 -> 0.375 | E5: =Recommendation!H15 -> 101164.6
A6: Merchandise | B6: =Recommendation!B9 -> 21 | C6: =Recommendation!D9 -> 21 | D6: =Recommendation!E9 -> 0.175 | E6: =Recommendation!H16 -> 26402.051
A7: Activities & Experiences | B7: =Recommendation!B10 -> 27 | C7: =Recommendation!D10 -> 54 | D7: =Recommendation!E10 -> 0.45 | E7: =Recommendation!H17 -> 27986.404
A8: Total | B8: =SUM(B5:B7) -> 93 | C8: =SUM(C5:C7) -> 120 | D8: =SUM(D5:D7) -> 1 | E8: =SUM(E5:E7) -> 155553.06
A10: Guest experience on the expected design day | B10: F&B | C10: Merchandise | D10: Activities
A11: Peak-hour utilization | B11: =Recommendation!C15 -> 0.81477582 | C11: =Recommendation!C16 -> 0.52385022 | D11: =Recommendation!C17 -> 0.78090508
A12: Peak-hour wait (minutes) | B12: =Recommendation!D15 -> 4.7987597 | C12: =Recommendation!D16 -> 1.6502692 | D12: =Recommendation!D17 -> 6.1101116
A13: Minimum booths from queueing alone | B13: =Demand!C13 -> 41 | C13: =Demand!C22 -> 14 | D13: =Demand!C31 -> 23
A15: Alternative | B15: F / M / A | C15: Contribution ($) | D15: Max wait (min) | E15: Feasible?
A16: =Recommendation!A25 -> Recommended (optimizer) | B16: =Recommendation!B25&" / "&Recommendation!C25&" / "&Recommendation!D25 -> 45 / 21 / 27 | C16: =Recommendation!K25 -> 155553.06 | D16: =Recommendation!I25 -> 6.1101116 | E16: =Recommendation!L25 -> Yes
A17: =Recommendation!A26 -> Revenue-per-space rule (max F&B) | B17: =Recommendation!B26&" / "&Recommendation!C26&" / "&Recommendation!D26 -> 60 / 36 / 12 | C17: =Recommendation!K26 -> 130502.74 | D17: =Recommendation!I26 -> 999 | E17: =Recommendation!L26 -> No
A18: =Recommendation!A27 -> Equal space per category | B18: =Recommendation!B27&" / "&Recommendation!C27&" / "&Recommendation!D27 -> 40 / 40 / 20 | C18: =Recommendation!K27 -> 136820.61 | D18: =Recommendation!I27 -> 45.195897 | E18: =Recommendation!L27 -> No
A19: =Recommendation!A28 -> Proportional to participation | B19: =Recommendation!B28&" / "&Recommendation!C28&" / "&Recommendation!D28 -> 52 / 22 / 23 | C19: =Recommendation!K28 -> 146072.9 | D19: =Recommendation!I28 -> 11.854746 | E19: =Recommendation!L28 -> No
A20: =Recommendation!A29 -> Queueing minimums only (slack unused) | B20: =Recommendation!B29&" / "&Recommendation!C29&" / "&Recommendation!D29 -> 41 / 14 / 23 | C20: =Recommendation!K29 -> 137570.95 | D20: =Recommendation!I29 -> 11.854746 | E20: =Recommendation!L29 -> No
A22: Stress test (recommended mix) | B22: Low day | C22: Expected day | D22: High day
A23: Max utilization | B23: =MAX(Recommendation!F34:H34) -> 0.6949115 | C23: =MAX(Recommendation!F35:H35) -> 0.81477582 | D23: =MAX(Recommendation!F36:H36) -> 1.0175651
A24: Contribution ($) | B24: =Recommendation!K34 -> 133491.45 | C24: =Recommendation!K35 -> 155553.06 | D24: =Recommendation!K36 -> 122347.96

Sheet Inputs
A1: Inputs and assumptions
A2: Blue = editable. Columns C/D/E = Low / Expected / High where the input varies by scenario; single-value inputs sit in column D.
A4: Parameter | B4: Key | C4: Low | D4: Expected | E4: High | F4: Source / rationale
A5: Demand (from Part 1 forecast)
A6: Design-day guests (Saturday of peak weekend) | B6: guests | C6: 9218 | D6: 10808 | E6: 13498 | F6: Part 1 model, Forecast!B34:D34 (peak weekend x 52% Saturday share). Expected is the sizing basis; Low/High are stress cases.
A7: Operating hours per day | B7: hours | D7: 10 | F7: Case: 10:00 AM to 8:00 PM.
A8: Maximum standard booth equivalents | B8: space_total | D8: 120 | F8: Case.
A10: Category economics (case ranges; Expected = midpoint)
A11: F&B spend per transaction ($) | B11: spend_F | C11: 18 | D11: 21.5 | E11: 25 | F11: Case: $18 to $25.
A12: Merchandise spend per transaction ($) | B12: spend_M | C12: 12 | D12: 16 | E12: 20 | F12: Case: $12 to $20.
A13: Activities spend per transaction ($) | B13: spend_A | C13: 5 | D13: 8.5 | E13: 12 | F13: Case: $5 to $12.
A14: F&B participation (% of guests) | B14: part_F | C14: 0.7 | D14: 0.775 | E14: 0.85 | F14: Case: 70 to 85%.
A15: Merchandise participation | B15: part_M | C15: 0.25 | D15: 0.325 | E15: 0.4 | F15: Case: 25 to 40%. Used as the base at the reference booth count (assortment effect below).
A16: Activities participation | B16: part_A | C16: 0.3 | D16: 0.4 | E16: 0.5 | F16: Case: 30 to 50%. Used as the base at the reference booth count.
A17: F&B operating cost (% of sales): 'High' | B17: cost_F | D17: 0.65 | F17: Prime cost (food + labor) benchmark is 55 to 65% of sales for F&B operators (mobile-cuisine.com; foodnhotelasia.com); festival booths add propane, disposables, permits and run peaky hours, so total operating cost is placed at the top of the range.
A18: Merchandise operating cost: 'Medium' | B18: cost_M | D18: 0.55 | F18: Retail keystone convention: COGS = 50% of selling price (50% gross margin), the stated expectation in gift and craft retail (priceva.com; craftybase.com); plus ~5% booth labor and packaging.
A19: Activities operating cost: 'Low-Medium' | B19: cost_A | D19: 0.4 | F19: Team judgment, structural: supplies 10 to 15% of a $5 to $12 ticket, staff 25 to 30%. Consistent with the case ranking it below Merchandise.
A20: Space per F&B booth | B20: space_F | D20: 1 | F20: Case.
A21: Space per Merchandise booth | B21: space_M | D21: 1 | F21: Case.
A22: Space per Activities booth | B22: space_A | D22: 2 | F22: Case: twice a standard booth.
A23: Festival commission on vendor sales (optional) | B23: commission | D23: 0 | F23: Set > 0 if leadership confirms a revenue-share model. Festival revenue = commission x gross sales (Recommendation sheet).
A25: Throughput and queueing
A26: F&B transactions per participating guest per day | B26: txn_F | D26: 1.5 | F26: Team assumption: a meal plus a snack or drink for half of participants. Drives peak-hour arrivals.
A27: Merchandise transactions per participating guest | B27: txn_M | D27: 1.1 | F27: Team assumption: mostly single purchases.
A28: Activities transactions per participating guest | B28: txn_A | D28: 1.2 | F28: Team assumption: some guests do more than one activity.
A29: F&B peak-hour share of daily transactions | B29: peak_F | D29: 0.15 | F29: Team assumption: lunch hour carries 15% of the day's food transactions (1.5x the 10% flat average).
A30: Merchandise peak-hour share | B30: peak_M | D30: 0.12 | F30: Team assumption: flatter than food.
A31: Activities peak-hour share | B31: peak_A | D31: 0.13 | F31: Team assumption: early-afternoon family peak.
A32: F&B service rate (transactions per booth per hour) | B32: mu_F | D32: 55 | F32: Team assumption: ~65 seconds per order at a single window with pre-made items. Editable; the most important throughput parameter.
A33: Merchandise service rate | B33: mu_M | D33: 40 | F33: Team assumption: ~90 seconds per sale including browsing conversion.
A34: Activities service rate | B34: mu_A | D34: 35 | F34: Team assumption: activities cycle guests in small groups; ~100 seconds per guest.
A35: Maximum peak-hour utilization (service-level constraint) | B35: rho_ok | D35: 0.85 | F35: Queueing rule of thumb: for an M/M/1 server, wait time grows as rho/(1-rho) and becomes unstable above ~85%. Standard capacity-planning threshold.
A36: Wait below which no guest balks (minutes) | B36: w_free | D36: 5 | F36: Team assumption.
A37: Wait at which all marginal peak-window guests balk (minutes) | B37: w_max | D37: 20 | F37: Team assumption. Balking is linear between w_free and w_max.
A38: Share of daily transactions occurring in the congested peak window | B38: p_win | D38: 0.45 | F38: Team assumption: ~3 hours near peak intensity carry 45% of the day's transactions; only this share is exposed to balking.
A40: Behavioral links between categories
A41: Dwell effect: F&B transactions per guest change per Activities booth above reference | B41: dwell | D41: 0.01 | F41: Team assumption: each Activities booth beyond 20 adds 1% to F&B transactions per guest (longer stays). Sensitivity: with 0 the optimum is 42/24/27; the recommendation barely moves.
A42: Reference Activities booth count | B42: ref_A | D42: 20 | F42: Anchor for the dwell and assortment effects.
A43: Reference Merchandise booth count | B43: ref_M | D43: 25 | F43: Anchor for the assortment effect.
A44: Assortment elasticity of participation (Merch and Activities) | B44: eps | D44: 0.3 | F44: Team assumption: participation = base x (booths / reference)^0.3, capped at the case maximum. More variety draws more participants, with diminishing returns.
...

Sheet Demand
A1: Step 1: Demand, peak-hour arrivals, and minimum booths (Little's Law + utilization target)
A3: Metric | B3: Low | C3: Expected | D3: High | E3: Logic
A4: Design-day guests | B4: =Inputs!$C$6 -> 9218 | C4: =Inputs!$D$6 -> 10808 | D4: =Inputs!$E$6 -> 13498 | E4: Part 1 peak day by scenario.
A5: Operating hours | B5: =Inputs!$D$7 -> 10 | C5: =Inputs!$D$7 -> 10 | D5: =Inputs!$D$7 -> 10
A7: Food & Beverage
A8: Participation (expected midpoint) | B8: =Inputs!$D$14 -> 0.775 | C8: =Inputs!$D$14 -> 0.775 | D8: =Inputs!$D$14 -> 0.775 | E8: Case midpoint. Scenario variation enters through guest count.
A9: Transactions per participating guest | B9: =Inputs!$D$26 -> 1.5 | C9: =Inputs!$D$26 -> 1.5 | D9: =Inputs!$D$26 -> 1.5 | E9: Inputs.
A10: Transactions per day | B10: =B$4*B8*B9 -> 10715.925 | C10: =C$4*C8*C9 -> 12564.3 | D10: =D$4*D8*D9 -> 15691.425 | E10: Guests x participation x transactions per guest.
A11: Peak-hour arrivals (lambda, per hour) | B11: =B10*Inputs!$D$29 -> 1607.3887 | C11: =C10*Inputs!$D$29 -> 1884.645 | D11: =D10*Inputs!$D$29 -> 2353.7137 | E11: Daily transactions x peak-hour share.
A12: Service rate per booth (mu, per hour) | B12: =Inputs!$D$32 -> 55 | C12: =Inputs!$D$32 -> 55 | D12: =Inputs!$D$32 -> 55 | E12: Inputs.
A13: Minimum booths at target utilization | B13: =ROUNDUP(B11/(B12*Inputs!$D$35),0) -> 35 | C13: =ROUNDUP(C11/(C12*Inputs!$D$35),0) -> 41 | D13: =ROUNDUP(D11/(D12*Inputs!$D$35),0) -> 51 | E13: ceil(lambda / (mu x rho_max)). Little's Law: servers needed = arrival rate / service rate per server.
A14: Space equivalents for minimum | B14: =B13*Inputs!$D$20 -> 35 | C14: =C13*Inputs!$D$20 -> 41 | D14: =D13*Inputs!$D$20 -> 51 | E14: Booths x space per booth.
A16: Merchandise
A17: Participation (expected midpoint) | B17: =Inputs!$D$15 -> 0.325 | C17: =Inputs!$D$15 -> 0.325 | D17: =Inputs!$D$15 -> 0.325 | E17: Case midpoint. Scenario variation enters through guest count.
A18: Transactions per participating guest | B18: =Inputs!$D$27 -> 1.1 | C18: =Inputs!$D$27 -> 1.1 | D18: =Inputs!$D$27 -> 1.1 | E18: Inputs.
A19: Transactions per day | B19: =B$4*B17*B18 -> 3295.435 | C19: =C$4*C17*C18 -> 3863.86 | D19: =D$4*D17*D18 -> 4825.535 | E19: Guests x participation x transactions per guest.
A20: Peak-hour arrivals (lambda, per hour) | B20: =B19*Inputs!$D$30 -> 395.4522 | C20: =C19*Inputs!$D$30 -> 463.6632 | D20: =D19*Inputs!$D$30 -> 579.0642 | E20: Daily transactions x peak-hour share.
A21: Service rate per booth (mu, per hour) | B21: =Inputs!$D$33 -> 40 | C21: =Inputs!$D$33 -> 40 | D21: =Inputs!$D$33 -> 40 | E21: Inputs.
A22: Minimum booths at target utilization | B22: =ROUNDUP(B20/(B21*Inputs!$D$35),0) -> 12 | C22: =ROUNDUP(C20/(C21*Inputs!$D$35),0) -> 14 | D22: =ROUNDUP(D20/(D21*Inputs!$D$35),0) -> 18 | E22: ceil(lambda / (mu x rho_max)). Little's Law: servers needed = arrival rate / service rate per server.
A23: Space equivalents for minimum | B23: =B22*Inputs!$D$21 -> 12 | C23: =C22*Inputs!$D$21 -> 14 | D23: =D22*Inputs!$D$21 -> 18 | E23: Booths x space per booth.
A25: Activities & Experiences
A26: Participation (expected midpoint) | B26: =Inputs!$D$16 -> 0.4 | C26: =Inputs!$D$16 -> 0.4 | D26: =Inputs!$D$16 -> 0.4 | E26: Case midpoint. Scenario variation enters through guest count.
A27: Transactions per participating guest | B27: =Inputs!$D$28 -> 1.2 | C27: =Inputs!$D$28 -> 1.2 | D27: =Inputs!$D$28 -> 1.2 | E27: Inputs.
A28: Transactions per day | B28: =B$4*B26*B27 -> 4424.64 | C28: =C$4*C26*C27 -> 5187.84 | D28: =D$4*D26*D27 -> 6479.04 | E28: Guests x participation x transactions per guest.
A29: Peak-hour arrivals (lambda, per hour) | B29: =B28*Inputs!$D$31 -> 575.2032 | C29: =C28*Inputs!$D$31 -> 674.4192 | D29: =D28*Inputs!$D$31 -> 842.2752 | E29: Daily transactions x peak-hour share.
A30: Service rate per booth (mu, per hour) | B30: =Inputs!$D$34 -> 35 | C30: =Inputs!$D$34 -> 35 | D30: =Inputs!$D$34 -> 35 | E30: Inputs.
A31: Minimum booths at target utilization | B31: =ROUNDUP(B29/(B30*Inputs!$D$35),0) -> 20 | C31: =ROUNDUP(C29/(C30*Inputs!$D$35),0) -> 23 | D31: =ROUNDUP(D29/(D30*Inputs!$D$35),0) -> 29 | E31: ceil(lambda / (mu x rho_max)). Little's Law: servers needed = arrival rate / service rate per server.
A32: Space equivalents for minimum | B32: =B31*Inputs!$D$22 -> 40 | C32: =C31*Inputs!$D$22 -> 46 | D32: =D31*Inputs!$D$22 -> 58 | E32: Booths x space per booth.
A34: Total space needed for minimums | B34: =B14+B23+B32 -> 87 | C34: =C14+C23+C32 -> 101 | D34: =D14+D23+D32 -> 127 | E34: Compare to 120. Slack is what the optimizer allocates; a value above 120 means the day cannot be served at target utilization without more capacity (Part 3 link).
A35: Slack (120 minus minimums) | B35: =Inputs!$D$8-B34 -> 33 | C35: =Inputs!$D$8-C34 -> 19 | D35: =Inputs!$D$8-D34 -> -7
A37: Contribution per guest per space (why revenue alone would choose all F&B)
A38: Category | B38: Sales per guest | C38: Contribution per guest | D38: Per space equivalent | E38: Ratio to F&B
A39: Food & Beverage | B39: =Inputs!$D$14*Inputs!$D$26*Inputs!$D$11 -> 24.99375 | C39: =B39*(1-Inputs!$D$17) -> 8.7478125 | D39: =C39/Inputs!$D$20 -> 8.7478125 | E39: =D39/$D$39 -> 1
A40: Merchandise | B40: =Inputs!$D$15*Inputs!$D$27*Inputs!$D$12 -> 5.72 | C40: =B40*(1-Inputs!$D$18) -> 2.574 | D40: =C40/Inputs!$D$21 -> 2.574 | E40: =D40/$D$39 -> 0.29424499
A41: Activities & Experiences | B41: =Inputs!$D$16*Inputs!$D$28*Inputs!$D$13 -> 4.08 | C41: =B41*(1-Inputs!$D$19) -> 2.448 | D41: =C41/Inputs!$D$22 -> 1.224 | E41: =D41/$D$39 -> 0.13992069

Sheet Optimizer
A1: Step 2: Integer program by exhaustive enumeration (every mix with F + M + 2A = 120)
A2: Each row is one candidate mix on the Expected design day. Feasible = all utilization <= target AND variety/feasibility bounds. Score = total contribution if feasible, else -1. Best row is selected by MAX. Do not edit this sheet; change Inputs.
A4: F booths | B4: A booths | C4: M booths | D4: Spaces used | E4: Merch participation | F4: Activities participation | G4: F&B txns/guest | H4: F lambda/hr | I4: F rho | J4: F wait (min) | K4: F balk frac | L4: F captured txns | M4: F sales | N4: F contribution | O4: M lambda/hr | P4: M rho | Q4: M wait (min) | R4: M balk frac | S4: M captured txns | T4: M sales | U4: M contribution | V4: A lambda/hr | W4: A rho | X4: A wait (min) | Y4: A balk frac | Z4: A captured txns | AA4: A sales | AB4: A contribution | AC4: Total sales | AD4: Total contribution | AE4: Max rho | AF4: Feasible (1/0) | AG4: Score
A5: 25 | B5: 10 | C5: =Inputs!$D$8-A5-Inputs!$D$22*B5 -> 75 | D5: =A5*Inputs!$D$20+C5*Inputs!$D$21+B5*Inputs!$D$22 -> 120 | E5: =MIN(Inputs!$E$15,Inputs!$D$15*(C5/Inputs!$D$43)^Inputs!$D$44) -> 0.4 | F5: =MIN(Inputs!$E$16,Inputs!$D$16*(B5/Inputs!$D$42)^Inputs!$D$44) -> 0.32490096 | G5: =Inputs!$D$26*(1+Inputs!$D$41*(B5-Inputs!$D$42)) -> 1.35 | H5: =Inputs!$D$6*Inputs!$D$14*G5*Inputs!$D$29 -> 1696.1805 | I5: =H5/(A5*Inputs!$D$32) -> 1.2335858 | J5: =IF(I5>=1,999,I5/(Inputs!$D$32*(1-I5))*60) -> 999 | K5: =MIN(1,MAX(0,(J5-Inputs!$D$36)/(Inputs!$D$37-Inputs!$D$36))) -> 1 | L5: =Inputs!$D$6*Inputs!$D$14*G5*(1-Inputs!$D$38*K5) -> 6219.3285 | M5: =L5*Inputs!$D$11 -> 133715.56 | N5: =M5*(1-Inputs!$D$17) -> 46800.447 | O5: =Inputs!$D$6*E5*Inputs!$D$27*Inputs!$D$30 -> 570.6624 | P5: =O5/(C5*Inputs!$D$33) -> 0.1902208 | Q5: =IF(P5>=1,999,P5/(Inputs!$D$33*(1-P5))*60) -> 0.35235679 | R5: =MIN(1,MAX(0,(Q5-Inputs!$D$36)/(Inputs!$D$37-Inputs!$D$36))) -> 0 | S5: =Inputs!$D$6*E5*Inputs!$D$27*(1-Inputs!$D$38*R5) -> 4755.52 | T5: =S5*Inputs!$D$12 -> 76088.32 | U5: =T5*(1-Inputs!$D$18) -> 34239.744 | V5: =Inputs!$D$6*F5*Inputs!$D$28*Inputs!$D$31 -> 547.79861 | W5: =V5/(B5*Inputs!$D$34) -> 1.5651389 | X5: =IF(W5>=1,999,W5/(Inputs!$D$34*(1-W5))*60) -> 999 | Y5: =MIN(1,MAX(0,(X5-Inputs!$D$36)/(Inputs!$D$37-Inputs!$D$36))) -> 1 | Z5: =Inputs!$D$6*F5*Inputs!$D$28*(1-Inputs!$D$38*Y5) -> 2317.6095 | AA5: =Z5*Inputs!$D$13 -> 19699.681 | AB5: =AA5*(1-Inputs!$D$19) -> 11819.808 | AC5: =M5+T5+AA5 -> 229503.56 | AD5: =N5+U5+AB5 -> 92859.999 | AE5: =MAX(I5,P5,W5) -> 1.5651389 | AF5: =IF(AND(AE5<=Inputs!$D$35,C5>=Inputs!$D$48*(A5+B5+C5),B5*Inputs!$D$22<=Inputs!$D$50*Inputs!$D$8,B5*Inputs!$D$22>=Inputs!$D$49*Inputs!$D$8,A5*Inputs!$D$20<=Inputs!$D$47*Inputs!$D$8,C5>=1),1,0) -> 0 | AG5: =IF(AF5=1,AD5,-1) -> -1
A6: 25 | B6: 11 | C6: =Inputs!$D$8-A6-Inputs!$D$22*B6 -> 73 | D6: =A6*Inputs!$D$20+C6*Inputs!$D$21+B6*Inputs!$D$22 -> 120 | E6: =MIN(Inputs!$E$15,Inputs!$D$15*(C6/Inputs!$D$43)^Inputs!$D$44) -> 0.4 | F6: =MIN(Inputs!$E$16,Inputs!$D$16*(B6/Inputs!$D$42)^Inputs!$D$44) -> 0.33432496 | G6: =Inputs!$D$26*(1+Inputs!$D$41*(B6-Inputs!$D$42)) -> 1.365 | H6: =Inputs!$D$6*Inputs!$D$14*G6*Inputs!$D$29 -> 1715.027 | I6: =H6/(A6*Inputs!$D$32) -> 1.2472923 | J6: =IF(I6>=1,999,I6/(Inputs!$D$32*(1-I6))*60) -> 999 | K6: =MIN(1,MAX(0,(J6-Inputs!$D$36)/(Inputs!$D$37-Inputs!$D$36))) -> 1 | L6: =Inputs!$D$6*Inputs!$D$14*G6*(1-Inputs!$D$38*K6) -> 6288.4322 | M6: =L6*Inputs!$D$11 -> 135201.29 | N6: =M6*(1-Inputs!$D$17) -> 47320.452 | O6: =Inputs!$D$6*E6*Inputs!$D$27*Inputs!$D$30 -> 570.6624 | P6: =O6/(C6*Inputs!$D$33) -> 0.19543233 | Q6: =IF(P6>=1,999,P6/(Inputs!$D$33*(1-P6))*60) -> 0.3643553 | R6: =MIN(1,MAX(0,(Q6-Inputs!$D$36)/(Inputs!$D$37-Inputs!$D$36))) -> 0 | S6: =Inputs!$D$6*E6*Inputs!$D$27*(1-Inputs!$D$38*R6) -> 4755.52 | T6: =S6*Inputs!$D$12 -> 76088.32 | U6: =T6*(1-Inputs!$D$18) -> 34239.744 | V6: =Inputs!$D$6*F6*Inputs!$D$28*Inputs!$D$31 -> 563.68793 | W6: =V6/(B6*Inputs!$D$34) -> 1.4641245 | X6: =IF(W6>=1,999,W6/(Inputs!$D$34*(1-W6))*60) -> 999 | Y6: =MIN(1,MAX(0,(X6-Inputs!$D$36)/(Inputs!$D$37-Inputs!$D$36))) -> 1 | Z6: =Inputs!$D$6*F6*Inputs!$D$28*(1-Inputs!$D$38*Y6) -> 2384.8335 | AA6: =Z6*Inputs!$D$13 -> 20271.085 | AB6: =AA6*(1-Inputs!$D$19) -> 12162.651 | AC6: =M6+T6+AA6 -> 231560.7 | AD6: =N6+U6+AB6 -> 93722.847 | AE6: =MAX(I6,P6,W6) -> 1.4641245 | AF6: =IF(AND(AE6<=Inputs!$D$35,C6>=Inputs!$D$48*(A6+B6+C6),B6*Inputs!$D$22<=Inputs!$D$50*Inputs!$D$8,B6*Inputs!$D$22>=Inputs!$D$49*Inputs!$D$8,A6*Inputs!$D$20<=Inputs!$D$47*Inputs!$D$8,C6>=1),1,0) -> 0 | AG6: =IF(AF6=1,AD6,-1) -> -1
A7: 25 | B7: 12 | C7: =Inputs!$D$8-A7-Inputs!$D$22*B7 -> 71 | D7: =A7*Inputs!$D$20+C7*Inputs!$D$21+B7*Inputs!$D$22 -> 120 | E7: =MIN(Inputs!$E$15,Inputs!$D$15*(C7/Inputs!$D$43)^Inputs!$D$44) -> 0.4 | F7: =MIN(Inputs!$E$16,Inputs!$D$16*(B7/Inputs!$D$42)^Inputs!$D$44) -> 0.34316688 | G7: =Inputs!$D$26*(1+Inputs!$D$41*(B7-Inputs!$D$42)) -> 1.38 | H7: =Inputs!$D$6*Inputs!$D$14*G7*Inputs!$D$29 -> 1733.8734 | I7: =H7/(A7*Inputs!$D$32) -> 1.2609988 | J7: =IF(I7>=1,999,I7/(Inputs!$D$32*(1-I7))*60) -> 999 | K7: =MIN(1,MAX(0,(J7-Inputs!$D$36)/(Inputs!$D$37-Inputs!$D$36))) -> 1 | L7: =Inputs!$D$6*Inputs!$D$14*G7*(1-Inputs!$D$38*K7) -> 6357.5358 | M7: =L7*Inputs!$D$11 -> 136687.02 | N7: =M7*(1-Inputs!$D$17) -> 47840.457 | O7: =Inputs!$D$6*E7*Inputs!$D$27*Inputs!$D$30 -> 570.6624 | P7: =O7/(C7*Inputs!$D$33) -> 0.20093746 | Q7: =IF(P7>=1,999,P7/(Inputs!$D$33*(1-P7))*60) -> 0.37719976 | R7: =MIN(1,MAX(0,(Q7-Inputs!$D$36)/(Inputs!$D$37-Inputs!$D$36))) -> 0 | S7: =Inputs!$D$6*E7*Inputs!$D$27*(1-Inputs!$D$38*R7) -> 4755.52 | T7: =S7*Inputs!$D$12 -> 76088.32 | U7: =T7*(1-Inputs!$D$18) -> 34239.744 | V7: =Inputs!$D$6*F7*Inputs!$D$28*Inputs!$D$31 -> 578.59583 | W7: =V7/(B7*Inputs!$D$34) -> 1.3776091 | X7: =IF(W7>=1,999,W7/(Inputs!$D$34*(1-W7))*60) -> 999 | Y7: =MIN(1,MAX(0,(X7-Inputs!$D$36)/(Inputs!$D$37-Inputs!$D$36))) -> 1 | Z7: =Inputs!$D$6*F7*Inputs!$D$28*(1-Inputs!$D$38*Y7) -> 2447.9054 | AA7: =Z7*Inputs!$D$13 -> 20807.196 | AB7: =AA7*(1-Inputs!$D$19) -> 12484.318 | AC7: =M7+T7+AA7 -> 233582.54 | AD7: =N7+U7+AB7 -> 94564.519 | AE7: =MAX(I7,P7,W7) -> 1.3776091 | AF7: =IF(AND(AE7<=Inputs!$D$35,C7>=Inputs!$D$48*(A7+B7+C7),B7*Inputs!$D$22<=Inputs!$D$50*Inputs!$D$8,B7*Inputs!$D$22>=Inputs!$D$49*Inputs!$D$8,A7*Inputs!$D$20<=Inputs!$D$47*Inputs!$D$8,C7>=1),1,0) -> 0 | AG7: =IF(AF7=1,AD7,-1) -> -1
A8: 25 | B8: 13 | C8: =Inputs!$D$8-A8-Inputs!$D$22*B8 -> 69 | D8: =A8*Inputs!$D$20+C8*Inputs!$D$21+B8*Inputs!$D$22 -> 120 | E8: =MIN(Inputs!$E$15,Inputs!$D$15*(C8/Inputs!$D$43)^Inputs!$D$44) -> 0.4 | F8: =MIN(Inputs!$E$16,Inputs!$D$16*(B8/Inputs!$D$42)^Inputs!$D$44) -> 0.35150702 | G8: =Inputs!$D$26*(1+Inputs!$D$41*(B8-Inputs!$D$42)) -> 1.395 | H8: =Inputs!$D$6*Inputs!$D$14*G8*Inputs!$D$29 -> 1752.7199 | I8: =H8/(A8*Inputs!$D$32) -> 1.2747053 | J8: =IF(I8>=1,999,I8/(Inputs!$D$32*(1-I8))*60) -> 999 | K8: =MIN(1,MAX(0,(J8-Inputs!$D$36)/(Inputs!$D$37-Inputs!$D$36))) -> 1 | L8: =Inputs!$D$6*Inputs!$D$14*G8*(1-Inputs!$D$38*K8) -> 6426.6395 | M8: =L8*Inputs!$D$11 -> 138172.75 | N8: =M8*(1-Inputs!$D$17) -> 48360.462 | O8: =Inputs!$D$6*E8*Inputs!$D$27*Inputs!$D$30 -> 570.6624 | P8: =O8/(C8*Inputs!$D$33) -> 0.20676174 | Q8: =IF(P8>=1,999,P8/(Inputs!$D$33*(1-P8))*60) -> 0.39098292 | R8: =MIN(1,MAX(0,(Q8-Inputs!$D$36)/(Inputs!$D$37-Inputs!$D$36))) -> 0 | S8: =Inputs!$D$6*E8*Inputs!$D$27*(1-Inputs!$D$38*R8) -> 4755.52 | T8: =S8*Inputs!$D$12 -> 76088.32 | U8: =T8*(1-Inputs!$D$18) -> 34239.744 | V8: =Inputs!$D$6*F8*Inputs!$D$28*Inputs!$D$31 -> 592.6577 | W8: =V8/(B8*Inputs!$D$34) -> 1.3025444 | X8: =IF(W8>=1,999,W8/(Inputs!$D$34*(1-W8))*60) -> 999 | Y8: =MIN(1,MAX(0,(X8-Inputs!$D$36)/(Inputs!$D$37-Inputs!$D$36))) -> 1 | Z8: =Inputs!$D$6*F8*Inputs!$D$28*(1-Inputs!$D$38*Y8) -> 2507.398 | AA8: =Z8*Inputs!$D$13 -> 21312.883 | AB8: =AA8*(1-Inputs!$D$19) -> 12787.73 | AC8: =M8+T8+AA8 -> 235573.95 | AD8: =N8+U8+AB8 -> 95387.936 | AE8: =MAX(I8,P8,W8) -> 1.3025444 | AF8: =IF(AND(AE8<=Inputs!$D$35,C8>=Inputs!$D$48*(A8+B8+C8),B8*Inputs!$D$22<=Inputs!$D$50*Inputs!$D$8,B8*Inputs!$D$22>=Inputs!$D$49*Inputs!$D$8,A8*Inputs!$D$20<=Inputs!$D$47*Inputs!$D$8,C8>=1),1,0) -> 0 | AG8: =IF(AF8=1,AD8,-1) -> -1
A9: 25 | B9: 14 | C9: =Inputs!$D$8-A9-Inputs!$D$22*B9 -> 67 | D9: =A9*Inputs!$D$20+C9*Inputs!$D$21+B9*Inputs!$D$22 -> 120 | E9: =MIN(Inputs!$E$15,Inputs!$D$15*(C9/Inputs!$D$43)^Inputs!$D$44) -> 0.4 | F9: =MIN(Inputs!$E$16,Inputs!$D$16*(B9/Inputs!$D$42)^Inputs!$D$44) -> 0.35940938 | G9: =Inputs!$D$26*(1+Inputs!$D$41*(B9-Inputs!$D$42)) -> 1.41 | H9: =Inputs!$D$6*Inputs!$D$14*G9*Inputs!$D$29 -> 1771.5663 | I9: =H9/(A9*Inputs!$D$32) -> 1.2884119 | J9: =IF(I9>=1,999,I9/(Inputs!$D$32*(1-I9))*60) -> 999 | K9: =MIN(1,MAX(0,(J9-Inputs!$D$36)/(Inputs!$D$37-Inputs!$D$36))) -> 1 | L9: =Inputs!$D$6*Inputs!$D$14*G9*(1-Inputs!$D$38*K9) -> 6495.7431 | M9: =L9*Inputs!$D$11 -> 139658.48 | N9: =M9*(1-Inputs!$D$17) -> 48880.467 | O9: =Inputs!$D$6*E9*Inputs!$D$27*Inputs!$D$30 -> 570.6624 | P9: =O9/(C9*Inputs!$D$33) -> 0.21293373 | Q9: =IF(P9>=1,999,P9/(Inputs!$D$33*(1-P9))*60) -> 0.40581157 | R9: =MIN(1,MAX(0,(Q9-Inputs!$D$36)/(Inputs!$D$37-Inputs!$D$36))) -> 0 | S9: =Inputs!$D$6*E9*Inputs!$D$27*(1-Inputs!$D$38*R9) -> 4755.52 | T9: =S9*Inputs!$D$12 -> 76088.32 | U9: =T9*(1-Inputs!$D$18) -> 34239.744 | V9: =Inputs!$D$6*F9*Inputs!$D$28*Inputs!$D$31 -> 605.98146 | W9: =V9/(B9*Inputs!$D$34) -> 1.2366969 | X9: =IF(W9>=1,999,W9/(Inputs!$D$34*(1-W9))*60) -> 999 | Y9: =MIN(1,MAX(0,(X9-Inputs!$D$36)/(Inputs!$D$37-Inputs!$D$36))) -> 1 | Z9: =Inputs!$D$6*F9*Inputs!$D$28*(1-Inputs!$D$38*Y9) -> 2563.7677 | AA9: =Z9*Inputs!$D$13 -> 21792.026 | AB9: =AA9*(1-Inputs!$D$19) -> 13075.215 | AC9: =M9+T9+AA9 -> 237538.82 | AD9: =N9+U9+AB9 -> 96195.426 | AE9: =MAX(I9,P9,W9) -> 1.2884119 | AF9: =IF(AND(AE9<=Inputs!$D$35,C9>=Inputs!$D$48*(A9+B9+C9),B9*Inputs!$D$22<=Inputs!$D$50*Inputs!$D$8,B9*Inputs!$D$22>=Inputs!$D$49*Inputs!$D$8,A9*Inputs!$D$20<=Inputs!$D$47*Inputs!$D$8,C9>=1),1,0) -> 0 | AG9: =IF(AF9=1,AD9,-1) -> -1
A10: 25 | B10: 15 | C10: =Inputs!$D$8-A10-Inputs!$D$22*B10 -> 65 | D10: =A10*Inputs!$D$20+C10*Inputs!$D$21+B10*Inputs!$D$22 -> 120 | E10: =MIN(Inputs!$E$15,Inputs!$D$15*(C10/Inputs!$D$43)^Inputs!$D$44) -> 0.4 | F10: =MIN(Inputs!$E$16,Inputs!$D$16*(B10/Inputs!$D$42)^Inputs!$D$44) -> 0.3669259 | G10: =Inputs!$D$26*(1+Inputs!$D$41*(B10-Inputs!$D$42)) -> 1.425 | H10: =Inputs!$D$6*Inputs!$D$14*G10*Inputs!$D$29 -> 1790.4127 | I10: =H10/(A10*Inputs!$D$32) -> 1.3021184 | J10: =IF(I10>=1,999,I10/(Inputs!$D$32*(1-I10))*60) -> 999 | K10: =MIN(1,MAX(0,(J10-Inputs!$D$36)/(Inputs!$D$37-Inputs!$D$36))) -> 1 | L10: =Inputs!$D$6*Inputs!$D$14*G10*(1-Inputs!$D$38*K10) -> 6564.8467 | M10: =L10*Inputs!$D$11 -> 141144.21 | N10: =M10*(1-Inputs!$D$17) -> 49400.472 | O10: =Inputs!$D$6*E10*Inputs!$D$27*Inputs!$D$30 -> 570.6624 | P10: =O10/(C10*Inputs!$D$33) -> 0.21948554 | Q10: =IF(P10>=1,999,P10/(Inputs!$D$33*(1-P10))*60) -> 0.42180936 | R10: =MIN(1,MAX(0,(Q10-Inputs!$D$36)/(Inputs!$D$37-Inputs!$D$36))) -> 0 | S10: =Inputs!$D$6*E10*Inputs!$D$27*(1-Inputs!$D$38*R10) -> 4755.52 | T10: =S10*Inputs!$D$12 -> 76088.32 | U10: =T10*(1-Inputs!$D$18) -> 34239.744 | V10: =Inputs!$D$6*F10*Inputs!$D$28*Inputs!$D$31 -> 618.65468 | W10: =V10/(B10*Inputs!$D$34) -> 1.1783899 | X10: =IF(W10>=1,999,W10/(Inputs!$D$34*(1-W10))*60) -> 999 | Y10: =MIN(1,MAX(0,(X10-Inputs!$D$36)/(Inputs!$D$37-Inputs!$D$36))) -> 1 | Z10: =Inputs!$D$6*F10*Inputs!$D$28*(1-Inputs!$D$38*Y10) -> 2617.3852 | AA10: =Z10*Inputs!$D$13 -> 22247.774 | AB10: =AA10*(1-Inputs!$D$19) -> 13348.665 | AC10: =M10+T10+AA10 -> 239480.3 | AD10: =N10+U10+AB10 -> 96988.88 | AE10: =MAX(I10,P10,W10) -> 1.3021184 | AF10: =IF(AND(AE10<=Inputs!$D$35,C10>=Inputs!$D$48*(A10+B10+C10),B10*Inputs!$D$22<=Inputs!$D$50*Inputs!$D$8,B10*Inputs!$D$22>=Inputs!$D$49*Inputs!$D$8,A10*Inputs!$D$20<=Inputs!$D$47*Inputs!$D$8,C10>=1),1,0) -> 0 | AG10: =IF(AF10=1,AD10,-1) -> -1
A11: 25 | B11: 16 | C11: =Inputs!$D$8-A11-Inputs!$D$22*B11 -> 63 | D11: =A11*Inputs!$D$20+C11*Inputs!$D$21+B11*Inputs!$D$22 -> 120 | E11: =MIN(Inputs!$E$15,Inputs!$D$15*(C11/Inputs!$D$43)^Inputs!$D$44) -> 0.4 | F11: =MIN(Inputs!$E$16,Inputs!$D$16*(B11/Inputs!$D$42)^Inputs!$D$44) -> 0.37409938 | G11: =Inputs!$D$26*(1+Inputs!$D$41*(B11-Inputs!$D$42)) -> 1.44 | H11: =Inputs!$D$6*Inputs!$D$14*G11*Inputs!$D$29 -> 1809.2592 | I11: =H11/(A11*Inputs!$D$32) -> 1.3158249 | J11: =IF(I11>=1,999,I11/(Inputs!$D$32*(1-I11))*60) -> 999 | K11: =MIN(1,MAX(0,(J11-Inputs!$D$36)/(Inputs!$D$37-Inputs!$D$36))) -> 1 | L11: =Inputs!$D$6*Inputs!$D$14*G11*(1-Inputs!$D$38*K11) -> 6633.9504 | M11: =L11*Inputs!$D$11 -> 142629.93 | N11: =M11*(1-Inputs!$D$17) -> 49920.477 | O11: =Inputs!$D$6*E11*Inputs!$D$27*Inputs!$D$30 -> 570.6624 | P11: =O11/(C11*Inputs!$D$33) -> 0.22645333 | Q11: =IF(P11>=1,999,P11/(Inputs!$D$33*(1-P11))*60) -> 0.43912024 | R11: =MIN(1,MAX(0,(Q11-Inputs!$D$36)/(Inputs!$D$37-Inputs!$D$36))) -> 0 | S11: =Inputs!$D$6*E11*Inputs!$D$27*(1-Inputs!$D$38*R11) -> 4755.52 | T11: =S11*Inputs!$D$12 -> 76088.32 | U11: =T11*(1-Inputs!$D$18) -> 34239.744 | V11: =Inputs!$D$6*F11*Inputs!$D$28*Inputs!$D$31 -> 630.74951 | W11: =V11/(B11*Inputs!$D$34) -> 1.1263384 | X11: =IF(W11>=1,999,W11/(Inputs!$D$34*(1-W11))*60) -> 999 | Y11: =MIN(1,MAX(0,(X11-Inputs!$D$36)/(Inputs!$D$37-Inputs!$D$36))) -> 1 | Z11: =Inputs!$D$6*F11*Inputs!$D$28*(1-Inputs!$D$38*Y11) -> 2668.5556 | AA11: =Z11*Inputs!$D$13 -> 22682.723 | AB11: =AA11*(1-Inputs!$D$19) -> 13609.634 | AC11: =M11+T11+AA11 -> 241400.98 | AD11: =N11+U11+AB11 -> 97769.854 | AE11: =MAX(I11,P11,W11) -> 1.3158249 | AF11: =IF(AND(AE11<=Inputs!$D$35,C11>=Inputs!$D$48*(A11+B11+C11),B11*Inputs!$D$22<=Inputs!$D$50*Inputs!$D$8,B11*Inputs!$D$22>=Inputs!$D$49*Inputs!$D$8,A11*Inputs!$D$20<=Inputs!$D$47*Inputs!$D$8,C11>=1),1,0) -> 0 | AG11: =IF(AF11=1,AD11,-1) -> -1
A12: 25 | B12: 17 | C12: =Inputs!$D$8-A12-Inputs!$D$22*B12 -> 61 | D12: =A12*Inputs!$D$20+C12*Inputs!$D$21+B12*Inputs!$D$22 -> 120 | E12: =MIN(Inputs!$E$15,Inputs!$D$15*(C12/Inputs!$D$43)^Inputs!$D$44) -> 0.4 | F12: =MIN(Inputs!$E$16,Inputs!$D$16*(B12/Inputs!$D$42)^Inputs!$D$44) -> 0.38096552 | G12: =Inputs!$D$26*(1+Inputs!$D$41*(B12-Inputs!$D$42)) -> 1.455 | H12: =Inputs!$D$6*Inputs!$D$14*G12*Inputs!$D$29 -> 1828.1057 | I12: =H12/(A12*Inputs!$D$32) -> 1.3295314 | J12: =IF(I12>=1,999,I12/(Inputs!$D$32*(1-I12))*60) -> 999 | K12: =MIN(1,MAX(0,(J12-Inputs!$D$36)/(Inputs!$D$37-Inputs!$D$36))) -> 1 | L12: =Inputs!$D$6*Inputs!$D$14*G12*(1-Inputs!$D$38*K12) -> 6703.0541 | M12: =L12*Inputs!$D$11 -> 144115.66 | N12: =M12*(1-Inputs!$D$17) -> 50440.482 | O12: =Inputs!$D$6*E12*Inputs!$D$27*Inputs!$D$30 -> 570.6624 | P12: =O12/(C12*Inputs!$D$33) -> 0.23387803 | Q12: =IF(P12>=1,999,P12/(Inputs!$D$33*(1-P12))*60) -> 0.45791279 | R12: =MIN(1,MAX(0,(Q12-Inputs!$D$36)/(Inputs!$D$37-Inputs!$D$36))) -> 0 | S12: =Inputs!$D$6*E12*Inputs!$D$27*(1-Inputs!$D$38*R12) -> 4755.52 | T12: =S12*Inputs!$D$12 -> 76088.32 | U12: =T12*(1-Inputs!$D$18) -> 34239.744 | V12: =Inputs!$D$6*F12*Inputs!$D$28*Inputs!$D$31 -> 642.32615 | W12: =V12/(B12*Inputs!$D$34) -> 1.0795397 | X12: =IF(W12>=1,999,W12/(Inputs!$D$34*(1-W12))*60) -> 999 | Y12: =MIN(1,MAX(0,(X12-Inputs!$D$36)/(Inputs!$D$37-Inputs!$D$36))) -> 1 | Z12: =Inputs!$D$6*F12*Inputs!$D$28*(1-Inputs!$D$38*Y12) -> 2717.5337 | AA12: =Z12*Inputs!$D$13 -> 23099.037 | AB12: =AA12*(1-Inputs!$D$19) -> 13859.422 | AC12: =M12+T12+AA12 -> 243303.02 | AD12: =N12+U12+AB12 -> 98539.648 | AE12: =MAX(I12,P12,W12) -> 1.3295314 | AF12: =IF(AND(AE12<=Inputs!$D$35,C12>=Inputs!$D$48*(A12+B12+C12),B12*Inputs!$D$22<=Inputs!$D$50*Inputs!$D$8,B12*Inputs!$D$22>=Inputs!$D$49*Inputs!$D$8,A12*Inputs!$D$20<=Inputs!$D$47*Inputs!$D$8,C12>=1),1,0) -> 0 | AG12: =IF(AF12=1,AD12,-1) -> -1
A13: 25 | B13: 18 | C13: =Inputs!$D$8-A13-Inputs!$D$22*B13 -> 59 | D13: =A13*Inputs!$D$20+C13*Inputs!$D$21+B13*Inputs!$D$22 -> 120 | E13: =MIN(Inputs!$E$15,Inputs!$D$15*(C13/Inputs!$D$43)^Inputs!$D$44) -> 0.4 | F13: =MIN(Inputs!$E$16,Inputs!$D$16*(B13/Inputs!$D$42)^Inputs!$D$44) -> 0.38755446 | G13: =Inputs!$D$26*(1+Inputs!$D$41*(B13-Inputs!$D$42)) -> 1.47 | H13: =Inputs!$D$6*Inputs!$D$14*G13*Inputs!$D$29 -> 1846.9521 | I13: =H13/(A13*Inputs!$D$32) -> 1.3432379 | J13: =IF(I13>=1,999,I13/(Inputs!$D$32*(1-I13))*60) -> 999 | K13: =MIN(1,MAX(0,(J13-Inputs!$D$36)/(Inputs!$D$37-Inputs!$D$36))) -> 1 | L13: =Inputs!$D$6*Inputs!$D$14*G13*(1-Inputs!$D$38*K13) -> 6772.1577 | M13: =L13*Inputs!$D$11 -> 145601.39 | N13: =M13*(1-Inputs!$D$17) -> 50960.487 | O13: =Inputs!$D$6*E13*Inputs!$D$27*Inputs!$D$30 -> 570.6624 | P13: =O13/(C13*Inputs!$D$33) -> 0.2418061 | Q13: =IF(P13>=1,999,P13/(Inputs!$D$33*(1-P13))*60) -> 0.47838574 | R13: =MIN(1,MAX(0,(Q13-Inputs!$D$36)/(Inputs!$D$37-Inputs!$D$36))) -> 0 | S13: =Inputs!$D$6*E13*Inputs!$D$27*(1-Inputs!$D$38*R13) -> 4755.52 | T13: =S13*Inputs!$D$12 -> 76088.32 | U13: =T13*(1-Inputs!$D$18) -> 34239.744 | V13: =Inputs!$D$6*F13*Inputs!$D$28*Inputs!$D$31 -> 653.43543 | W13: =V13/(B13*Inputs!$D$34) -> 1.0371991 | X13: =IF(W13>=1,999,W13/(Inputs!$D$34*(1-W13))*60) -> 999 | Y13: =MIN(1,MAX(0,(X13-Inputs!$D$36)/(Inputs!$D$37-Inputs!$D$36))) -> 1 | Z13: =Inputs!$D$6*F13*Inputs!$D$28*(1-Inputs!$D$38*Y13) -> 2764.5345 | AA13: =Z13*Inputs!$D$13 -> 23498.543 | AB13: =AA13*(1-Inputs!$D$19) -> 14099.126 | AC13: =M13+T13+AA13 -> 245188.25 | AD13: =N13+U13+AB13 -> 99299.357 | AE13: =MAX(I13,P13,W13) -> 1.3432379 | AF13: =IF(AND(AE13<=Inputs!$D$35,C13>=Inputs!$D$48*(A13+B13+C13),B13*Inputs!$D$22<=Inputs!$D$50*Inputs!$D$8,B13*Inputs!$D$22>=Inputs!$D$49*Inputs!$D$8,A13*Inputs!$D$20<=Inputs!$D$47*Inputs!$D$8,C13>=1),1,0) -> 0 | AG13: =IF(AF13=1,AD13,-1) -> -1
A14: 25 | B14: 19 | C14: =Inputs!$D$8-A14-Inputs!$D$22*B14 -> 57 | D14: =A14*Inputs!$D$20+C14*Inputs!$D$21+B14*Inputs!$D$22 -> 120 | E14: =MIN(Inputs!$E$15,Inputs!$D$15*(C14/Inputs!$D$43)^Inputs!$D$44) -> 0.4 | F14: =MIN(Inputs!$E$16,Inputs!$D$16*(B14/Inputs!$D$42)^Inputs!$D$44) -> 0.39389192 | G14: =Inputs!$D$26*(1+Inputs!$D$41*(B14-Inputs!$D$42)) -> 1.485 | H14: =Inputs!$D$6*Inputs!$D$14*G14*Inputs!$D$29 -> 1865.7985 | I14: =H14/(A14*Inputs!$D$32) -> 1.3569444 | J14: =IF(I14>=1,999,I14/(Inputs!$D$32*(1-I14))*60) -> 999 | K14: =MIN(1,MAX(0,(J14-Inputs!$D$36)/(Inputs!$D$37-Inputs!$D$36))) -> 1 | L14: =Inputs!$D$6*Inputs!$D$14*G14*(1-Inputs!$D$38*K14) -> 6841.2613 | M14: =L14*Inputs!$D$11 -> 147087.12 | N14: =M14*(1-Inputs!$D$17) -> 51480.492 | O14: =Inputs!$D$6*E14*Inputs!$D$27*Inputs!$D$30 -> 570.6624 | P14: =O14/(C14*Inputs!$D$33) -> 0.25029053 | Q14: =IF(P14>=1,999,P14/(Inputs!$D$33*(1-P14))*60) -> 0.50077504 | R14: =MIN(1,MAX(0,(Q14-Inputs!$D$36)/(Inputs!$D$37-Inputs!$D$36))) -> 0 | S14: =Inputs!$D$6*E14*Inputs!$D$27*(1-Inputs!$D$38*R14) -> 4755.52 | T14: =S14*Inputs!$D$12 -> 76088.32 | U14: =T14*(1-Inputs!$D$18) -> 34239.744 | V14: =Inputs!$D$6*F14*Inputs!$D$28*Inputs!$D$31 -> 664.12069 | W14: =V14/(B14*Inputs!$D$34) -> 0.99867772 | X14: =IF(W14>=1,999,W14/(Inputs!$D$34*(1-W14))*60) -> 1294.7497 | Y14: =MIN(1,MAX(0,(X14-Inputs!$D$36)/(Inputs!$D$37-Inputs!$D$36))) -> 1 | Z14: =Inputs!$D$6*F14*Inputs!$D$28*(1-Inputs!$D$38*Y14) -> 2809.7414 | AA14: =Z14*Inputs!$D$13 -> 23882.802 | AB14: =AA14*(1-Inputs!$D$19) -> 14329.681 | AC14: =M14+T14+AA14 -> 247058.24 | AD14: =N14+U14+AB14 -> 100049.92 | AE14: =MAX(I14,P14,W14) -> 1.3569444 | AF14: =IF(AND(AE14<=Inputs!$D$35,C14>=Inputs!$D$48*(A14+B14+C14),B14*Inputs!$D$22<=Inputs!$D$50*Inputs!$D$8,B14*Inputs!$D$22>=Inputs!$D$49*Inputs!$D$8,A14*Inputs!$D$20<=Inputs!$D$47*Inputs!$D$8,C14>=1),1,0) -> 0 | AG14: =IF(AF14=1,AD14,-1) -> -1
A15: 25 | B15: 20 | C15: =Inputs!$D$8-A15-Inputs!$D$22*B15 -> 55 | D15: =A15*Inputs!$D$20+C15*Inputs!$D$21+B15*Inputs!$D$22 -> 120 | E15: =MIN(Inputs!$E$15,Inputs!$D$15*(C15/Inputs!$D$43)^Inputs!$D$44) -> 0.4 | F15: =MIN(Inputs!$E$16,Inputs!$D$16*(B15/Inputs!$D$42)^Inputs!$D$44) -> 0.4 | G15: =Inputs!$D$26*(1+Inputs!$D$41*(B15-Inputs!$D$42)) -> 1.5 | H15: =Inputs!$D$6*Inputs!$D$14*G15*Inputs!$D$29 -> 1884.645 | I15: =H15/(A15*Inputs!$D$32) -> 1.3706509 | J15: =IF(I15>=1,999,I15/(Inputs!$D$32*(1-I15))*60) -> 999 | K15: =MIN(1,MAX(0,(J15-Inputs!$D$36)/(Inputs!$D$37-Inputs!$D$36))) -> 1 | L15: =Inputs!$D$6*Inputs!$D$14*G15*(1-Inputs!$D$38*K15) -> 6910.365 | M15: =L15*Inputs!$D$11 -> 148572.85 | N15: =M15*(1-Inputs!$D$17) -> 52000.497 | O15: =Inputs!$D$6*E15*Inputs!$D$27*Inputs!$D$30 -> 570.6624 | P15: =O15/(C15*Inputs!$D$33) -> 0.259392 | Q15: =IF(P15>=1,999,P15/(Inputs!$D$33*(1-P15))*60) -> 0.52536295 | R15: =MIN(1,MAX(0,(Q15-Inputs!$D$36)/(Inputs!$D$37-Inputs!$D$36))) -> 0 | S15: =Inputs!$D$6*E15*Inputs!$D$27*(1-Inputs!$D$38*R15) -> 4755.52 | T15: =S15*Inputs!$D$12 -> 76088.32 | U15: =T15*(1-Inputs!$D$18) -> 34239.744 | V15: =Inputs!$D$6*F15*Inputs!$D$28*Inputs!$D$31 -> 674.4192 | W15: =V15/(B15*Inputs!$D$34) -> 0.963456 | X15: =IF(W15>=1,999,W15/(Inputs!$D$34*(1-W15))*60) -> 45.195897 | Y15: =MIN(1,MAX(0,(X15-Inputs!$D$36)/(Inputs!$D$37-Inputs!$D$36))) -> 1 | Z15: =Inputs!$D$6*F15*Inputs!$D$28*(1-Inputs!$D$38*Y15) -> 2853.312 | AA15: =Z15*Inputs!$D$13 -> 24253.152 | AB15: =AA15*(1-Inputs!$D$19) -> 14551.891 | AC15: =M15+T15+AA15 -> 248914.32 | AD15: =N15+U15+AB15 -> 100792.13 | AE15: =MAX(I15,P15,W15) -> 1.3706509 | AF15: =IF(AND(AE15<=Inputs!$D$35,C15>=Inputs!$D$48*(A15+B15+C15),B15*Inputs!$D$22<=Inputs!$D$50*Inputs!$D$8,B15*Inputs!$D$22>=Inputs!$D$49*Inputs!$D$8,A15*Inputs!$D$20<=Inputs!$D$47*Inputs!$D$8,C15>=1),1,0) -> 0 | AG15: =IF(AF15=1,AD15,-1) -> -1
A16: 25 | B16: 21 | C16: =Inputs!$D$8-A16-Inputs!$D$22*B16 -> 53 | D16: =A16*Inputs!$D$20+C16*Inputs!$D$21+B16*Inputs!$D$22 -> 120 | E16: =MIN(Inputs!$E$15,Inputs!$D$15*(C16/Inputs!$D$43)^Inputs!$D$44) -> 0.4 | F16: =MIN(Inputs!$E$16,Inputs!$D$16*(B16/Inputs!$D$42)^Inputs!$D$44) -> 0.40589788 | G16: =Inputs!$D$26*(1+Inputs!$D$41*(B16-Inputs!$D$42)) -> 1.515 | H16: =Inputs!$D$6*Inputs!$D$14*G16*Inputs!$D$29 -> 1903.4915 | I16: =H16/(A16*Inputs!$D$32) -> 1.3843574 | J16: =IF(I16>=1,999,I16/(Inputs!$D$32*(1-I16))*60) -> 999 | K16: =MIN(1,MAX(0,(J16-Inputs!$D$36)/(Inputs!$D$37-Inputs!$D$36))) -> 1 | L16: =Inputs!$D$6*Inputs!$D$14*G16*(1-Inputs!$D$38*K16) -> 6979.4687 | M16: =L16*Inputs!$D$11 -> 150058.58 | N16: =M16*(1-Inputs!$D$17) -> 52520.502 | O16: =Inputs!$D$6*E16*Inputs!$D$27*Inputs!$D$30 -> 570.6624 | P16: =O16/(C16*Inputs!$D$33) -> 0.26918038 | Q16: =IF(P16>=1,999,P16/(Inputs!$D$33*(1-P16))*60) -> 0.55249004 | R16: =MIN(1,MAX(0,(Q16-Inputs!$D$36)/(Inputs!$D$37-Inputs!$D$36))) -> 0 | S16: =Inputs!$D$6*E16*Inputs!$D$27*(1-Inputs!$D$38*R16) -> 4755.52 | T16: =S16*Inputs!$D$12 -> 76088.32 | U16: =T16*(1-Inputs!$D$18) -> 34239.744 | V16: =Inputs!$D$6*F16*Inputs!$D$28*Inputs!$D$31 -> 684.36331 | W16: =V16/(B16*Inputs!$D$34) -> 0.93110654 | X16: =IF(W16>=1,999,W16/(Inputs!$D$34*(1-W16))*60) -> 23.168855 | Y16: =MIN(1,MAX(0,(X16-Inputs!$D$36)/(Inputs!$D$37-Inputs!$D$36))) -> 1 | Z16: =Inputs!$D$6*F16*Inputs!$D$28*(1-Inputs!$D$38*Y16) -> 2895.3832 | AA16: =Z16*Inputs!$D$13 -> 24610.757 | AB16: =AA16*(1-Inputs!$D$19) -> 14766.454 | AC16: =M16+T16+AA16 -> 250757.65 | AD16: =N16+U16+AB16 -> 101526.7 | AE16: =MAX(I16,P16,W16) -> 1.3843574 | AF16: =IF(AND(AE16<=Inputs!$D$35,C16>=Inputs!$D$48*(A16+B16+C16),B16*Inputs!$D$22<=Inputs!$D$50*Inputs!$D$8,B16*Inputs!$D$22>=Inputs!$D$49*Inputs!$D$8,A16*Inputs!$D$20<=Inputs!$D$47*Inputs!$D$8,C16>=1),1,0) -> 0 | AG16: =IF(AF16=1,AD16,-1) -> -1
... A946: 65 | B946: 27 | C946: =Inputs!$D$8-A946-Inputs!$D$22*B946 -> 1 | D946: =A946*Inputs!$D$20+C946*Inputs!$D$21+B946*Inputs!$D$22 -> 120 | E946: =MIN(Inputs!$E$15,Inputs!$D$15*(C946/Inputs!$D$43)^Inputs!$D$44) -> 0.12373751 | F946: =MIN(Inputs!$E$16,Inputs!$D$16*(B946/Inputs!$D$42)^Inputs!$D$44) -> 0.43768345 | G946: =Inputs!$D$26*(1+Inputs!$D$41*(B946-Inputs!$D$42)) -> 1.605 | H946: =Inputs!$D$6*Inputs!$D$14*G946*Inputs!$D$29 -> 2016.5702 | I946: =H946/(A946*Inputs!$D$32) -> 0.56407557 | J946: =IF(I946>=1,999,I946/(Inputs!$D$32*(1-I946))*60) -> 1.4116097 | K946: =MIN(1,MAX(0,(J946-Inputs!$D$36)/(Inputs!$D$37-Inputs!$D$36))) -> 0 | L946: =Inputs!$D$6*Inputs!$D$14*G946*(1-Inputs!$D$38*K946) -> 13443.801 | M946: =L946*Inputs!$D$11 -> 289041.72 | N946: =M946*(1-Inputs!$D$17) -> 101164.6 | O946: =Inputs!$D$6*E946*Inputs!$D$27*Inputs!$D$30 -> 176.53086 | P946: =O946/(C946*Inputs!$D$33) -> 4.4132714 | Q946: =IF(P946>=1,999,P946/(Inputs!$D$33*(1-P946))*60) -> 999 | R946: =MIN(1,MAX(0,(Q946-Inputs!$D$36)/(Inputs!$D$37-Inputs!$D$36))) -> 1 | S946: =Inputs!$D$6*E946*Inputs!$D$27*(1-Inputs!$D$38*R946) -> 809.09975 | T946: =S946*Inputs!$D$12 -> 12945.596 | U946: =T946*(1-Inputs!$D$18) -> 5825.5182 | V946: =Inputs!$D$6*F946*Inputs!$D$28*Inputs!$D$31 -> 737.9553 | W946: =V946/(B946*Inputs!$D$34) -> 0.78090508 | X946: =IF(W946>=1,999,W946/(Inputs!$D$34*(1-W946))*60) -> 6.1101116 | Y946: =MIN(1,MAX(0,(X946-Inputs!$D$36)/(Inputs!$D$37-Inputs!$D$36))) -> 0.074007442 | Z946: =Inputs!$D$6*F946*Inputs!$D$28*(1-Inputs!$D$38*Y946) -> 5487.5301 | AA946: =Z946*Inputs!$D$13 -> 46644.006 | AB946: =AA946*(1-Inputs!$D$19) -> 27986.404 | AC946: =M946+T946+AA946 -> 348631.32 | AD946: =N946+U946+AB946 -> 134976.52 | AE946: =MAX(I946,P946,W946) -> 4.4132714 | AF946: =IF(AND(AE946<=Inputs!$D$35,C946>=Inputs!$D$48*(A946+B946+C946),B946*Inputs!$D$22<=Inputs!$D$50*Inputs!$D$8,B946*Inputs!$D$22>=Inputs!$D$49*Inputs!$D$8,A946*Inputs!$D$20<=Inputs!$D$47*Inputs!$D$8,C946>=1),1,0) -> 0 | AG946: =IF(AF946=1,AD946,-1) -> -1

Sheet Recommendation
A1: Step 3: Recommended booth mix, alternatives, and stress test
A3: Best feasible score (contribution, expected design day) | B3: =MAX(Optimizer!$AG$5:$AG$946) -> 155553.06
A4: Row of best mix in Optimizer | B4: =MATCH(B3,Optimizer!$AG$5:$AG$946,0) -> 498
A5: Feasible mixes found | B5: =COUNTIF(Optimizer!$AF$5:$AF$946,1) -> 49
A7: Recommended mix | B7: Booths | C7: Space per booth | D7: Space equivalents | E7: Share of space
A8: Food & Beverage | B8: =INDEX(Optimizer!$A$5:$A$946,$B$4) -> 45 | C8: =Inputs!$D$20 -> 1 | D8: =B8*C8 -> 45 | E8: =D8/Inputs!$D$8 -> 0.375
A9: Merchandise | B9: =INDEX(Optimizer!$C$5:$C$946,$B$4) -> 21 | C9: =Inputs!$D$21 -> 1 | D9: =B9*C9 -> 21 | E9: =D9/Inputs!$D$8 -> 0.175
A10: Activities & Experiences | B10: =INDEX(Optimizer!$B$5:$B$946,$B$4) -> 27 | C10: =Inputs!$D$22 -> 2 | D10: =B10*C10 -> 54 | E10: =D10/Inputs!$D$8 -> 0.45
A11: Total | B11: =SUM(B8:B10) -> 93 | D11: =SUM(D8:D10) -> 120 | E11: =SUM(E8:E10) -> 1
A12: Check: space used = 120 | B12: =IF(D11=Inputs!$D$8,"OK","ERROR") -> OK
A14: Expected design day, by category | B14: Peak-hour arrivals | C14: Utilization | D14: Peak wait (min) | E14: Balk fraction | F14: Captured transactions | G14: Gross sales ($) | H14: Contribution ($)
A15: Food & Beverage | B15: =INDEX(Optimizer!$H$5:$H$946,$B$4) -> 2016.5702 | C15: =INDEX(Optimizer!$I$5:$I$946,$B$4) -> 0.81477582 | D15: =INDEX(Optimizer!$J$5:$J$946,$B$4) -> 4.7987597 | E15: =INDEX(Optimizer!$K$5:$K$946,$B$4) -> 0 | F15: =INDEX(Optimizer!$L$5:$L$946,$B$4) -> 13443.801 | G15: =INDEX(Optimizer!$M$5:$M$946,$B$4) -> 289041.72 | H15: =INDEX(Optimizer!$N$5:$N$946,$B$4) -> 101164.6
A16: Merchandise | B16: =INDEX(Optimizer!$O$5:$O$946,$B$4) -> 440.03418 | C16: =INDEX(Optimizer!$P$5:$P$946,$B$4) -> 0.52385022 | D16: =INDEX(Optimizer!$Q$5:$Q$946,$B$4) -> 1.6502692 | E16: =INDEX(Optimizer!$R$5:$R$946,$B$4) -> 0 | F16: =INDEX(Optimizer!$S$5:$S$946,$B$4) -> 3666.9515 | G16: =INDEX(Optimizer!$T$5:$T$946,$B$4) -> 58671.224 | H16: =INDEX(Optimizer!$U$5:$U$946,$B$4) -> 26402.051
A17: Activities & Experiences | B17: =INDEX(Optimizer!$V$5:$V$946,$B$4) -> 737.9553 | C17: =INDEX(Optimizer!$W$5:$W$946,$B$4) -> 0.78090508 | D17: =INDEX(Optimizer!$X$5:$X$946,$B$4) -> 6.1101116 | E17: =INDEX(Optimizer!$Y$5:$Y$946,$B$4) -> 0.074007442 | F17: =INDEX(Optimizer!$Z$5:$Z$946,$B$4) -> 5487.5301 | G17: =INDEX(Optimizer!$AA$5:$AA$946,$B$4) -> 46644.006 | H17: =INDEX(Optimizer!$AB$5:$AB$946,$B$4) -> 27986.404
A18: Total | B18: =SUM(B15:B17) -> 3194.5596 | F18: =SUM(F15:F17) -> 22598.283 | G18: =SUM(G15:G17) -> 394356.95 | H18: =SUM(H15:H17) -> 155553.06
A19: Festival revenue if commission model (commission x gross sales) | G19: =G18*Inputs!$D$23 -> 0
A20: Contribution per space equivalent (design day) | H20: =H18/Inputs!$D$8 -> 1296.2755
A21: Season estimate: design-day contribution scaled by (season total guests / design-day guests) | H21: =H18/Inputs!$D$6*67998 -> 978654.4
A23: Alternatives evaluated with the same model (why the recommendation beats intuitive rules)
A24: Alternative | B24: F | C24: M | D24: A | E24: Spaces | F24: F rho | G24: M rho | H24: A rho | I24: Max wait (min) | J24: Gross sales ($) | K24: Contribution ($) | L24: Feasible?
A25: Recommended (optimizer) | B25: =B8 -> 45 | C25: =B9 -> 21 | D25: =B10 -> 27 | E25: =B25*Inputs!$D$20+C25*Inputs!$D$21+D25*Inputs!$D$22 -> 120 | F25: =(Inputs!$D$6*Inputs!$D$14*Inputs!$D$26*(1+Inputs!$D$41*(D25-Inputs!$D$42))*Inputs!$D$29/(B25*Inputs!$D$32)) -> 0.81477582 | G25: =(Inputs!$D$6*MIN(Inputs!$E$15,Inputs!$D$15*(C25/Inputs!$D$43)^Inputs!$D$44)*Inputs!$D$27*Inputs!$D$30/(C25*Inputs!$D$33)) -> 0.52385022 | H25: =(Inputs!$D$6*MIN(Inputs!$E$16,Inputs!$D$16*(D25/Inputs!$D$42)^Inputs!$D$44)*Inputs!$D$28*Inputs!$D$31/(D25*Inputs!$D$34)) -> 0.78090508 | I25: =MAX(IF(F25>=1,999,F25/(Inputs!$D$32*(1-F25))*60),IF(G25>=1,999,G25/(Inputs!$D$33*(1-G25))*60),IF(H25>=1,999,H25/(Inputs!$D$34*(1-H25))*60)) -> 6.1101116 | J25: =(Inputs!$D$6*Inputs!$D$14*Inputs!$D$26*(1+Inputs!$D$41*(D25-Inputs!$D$42))*(1-Inputs!$D$38*MIN(1,MAX(0,(IF(F25>=1,999,F25/(Inputs!$D$32*(1-F25))*60)-Inputs!$D$36)/(Inputs!$D$37-Inputs!$D$36))))*Inputs!$D$11)+(Inputs!$D$6*MIN(Inputs!$E$15,Inputs!$D$15*(C25/Inputs!$D$43)^Inputs!$D$44)*Inputs!$D$27*(1-Inputs!$D$38*MIN(1,MAX(0,(IF(G25>=1,999,G25/(Inputs!$D$33*(1-G25))*60)-Inputs!$D$36)/(Inputs!$D$37-Inputs!$D$36))))*Inputs!$D$12)+(Inputs!$D$6*MIN(Inputs!$E$16,Inputs!$D$16*(D25/Inputs!$D$42)^Inputs!$D$44)*Inputs!$D$28*(1-Inputs!$D$38*MIN(1,MAX(0,(IF(H25>=1,999,H25/(Inputs!$D$34*(1-H25))*60)-Inputs!$D$36)/(Inputs!$D$37-Inputs!$D$36))))*Inputs!$D$13) -> 394356.95 | K25: =(Inputs!$D$6*Inputs!$D$14*Inputs!$D$26*(1+Inputs!$D$41*(D25-Inputs!$D$42))*(1-Inputs!$D$38*MIN(1,MAX(0,(IF(F25>=1,999,F25/(Inputs!$D$32*(1-F25))*60)-Inputs!$D$36)/(Inputs!$D$37-Inputs!$D$36))))*Inputs!$D$11)*(1-Inputs!$D$17)+(Inputs!$D$6*MIN(Inputs!$E$15,Inputs!$D$15*(C25/Inputs!$D$43)^Inputs!$D$44)*Inputs!$D$27*(1-Inputs!$D$38*MIN(1,MAX(0,(IF(G25>=1,999,G25/(Inputs!$D$33*(1-G25))*60)-Inputs!$D$36)/(Inputs!$D$37-Inputs!$D$36))))*Inputs!$D$12)*(1-Inputs!$D$18)+(Inputs!$D$6*MIN(Inputs!$E$16,Inputs!$D$16*(D25/Inputs!$D$42)^Inputs!$D$44)*Inputs!$D$28*(1-Inputs!$D$38*MIN(1,MAX(0,(IF(H25>=1,999,H25/(Inputs!$D$34*(1-H25))*60)-Inputs!$D$36)/(Inputs!$D$37-Inputs!$D$36))))*Inputs!$D$13)*(1-Inputs!$D$19) -> 155553.06 | L25: =IF(AND(MAX(F25,G25,H25)<=Inputs!$D$35,E25<=Inputs!$D$8),"Yes","No") -> Yes
A26: Revenue-per-space rule (max F&B) | B26: 60 | C26: 36 | D26: 12 | E26: =B26*Inputs!$D$20+C26*Inputs!$D$21+D26*Inputs!$D$22 -> 120 | F26: =(Inputs!$D$6*Inputs!$D$14*Inputs!$D$26*(1+Inputs!$D$41*(D26-Inputs!$D$42))*Inputs!$D$29/(B26*Inputs!$D$32)) -> 0.52541618 | G26: =(Inputs!$D$6*MIN(Inputs!$E$15,Inputs!$D$15*(C26/Inputs!$D$43)^Inputs!$D$44)*Inputs!$D$27*Inputs!$D$30/(C26*Inputs!$D$33)) -> 0.35921038 | H26: =(Inputs!$D$6*MIN(Inputs!$E$16,Inputs!$D$16*(D26/Inputs!$D$42)^Inputs!$D$44)*Inputs!$D$28*Inputs!$D$31/(D26*Inputs!$D$34)) -> 1.3776091 | I26: =MAX(IF(F26>=1,999,F26/(Inputs!$D$32*(1-F26))*60),IF(G26>=1,999,G26/(Inputs!$D$33*(1-G26))*60),IF(H26>=1,999,H26/(Inputs!$D$34*(1-H26))*60)) -> 999 | J26: =(Inputs!$D$6*Inputs!$D$14*Inputs!$D$26*(1+Inputs!$D$41*(D26-Inputs!$D$42))*(1-Inputs!$D$38*MIN(1,MAX(0,(IF(F26>=1,999,F26/(Inputs!$D$32*(1-F26))*60)-Inputs!$D$36)/(Inputs!$D$37-Inputs!$D$36))))*Inputs!$D$11)+(Inputs!$D$6*MIN(Inputs!$E$15,Inputs!$D$15*(C26/Inputs!$D$43)^Inputs!$D$44)*Inputs!$D$27*(1-Inputs!$D$38*MIN(1,MAX(0,(IF(G26>=1,999,G26/(Inputs!$D$33*(1-G26))*60)-Inputs!$D$36)/(Inputs!$D$37-Inputs!$D$36))))*Inputs!$D$12)+(Inputs!$D$6*MIN(Inputs!$E$16,Inputs!$D$16*(D26/Inputs!$D$42)^Inputs!$D$44)*Inputs!$D$28*(1-Inputs!$D$38*MIN(1,MAX(0,(IF(H26>=1,999,H26/(Inputs!$D$34*(1-H26))*60)-Inputs!$D$36)/(Inputs!$D$37-Inputs!$D$36))))*Inputs!$D$13) -> 338297.44 | K26: =(Inputs!$D$6*Inputs!$D$14*Inputs!$D$26*(1+Inputs!$D$41*(D26-Inputs!$D$42))*(1-Inputs!$D$38*MIN(1,MAX(0,(IF(F26>=1,999,F26/(Inputs!$D$32*(1-F26))*60)-Inputs!$D$36)/(Inputs!$D$37-Inputs!$D$36))))*Inputs!$D$11)*(1-Inputs!$D$17)+(Inputs!$D$6*MIN(Inputs!$E$15,Inputs!$D$15*(C26/Inputs!$D$43)^Inputs!$D$44)*Inputs!$D$27*(1-Inputs!$D$38*MIN(1,MAX(0,(IF(G26>=1,999,G26/(Inputs!$D$33*(1-G26))*60)-Inputs!$D$36)/(Inputs!$D$37-Inputs!$D$36))))*Inputs!$D$12)*(1-Inputs!$D$18)+(Inputs!$D$6*MIN(Inputs!$E$16,Inputs!$D$16*(D26/Inputs!$D$42)^Inputs!$D$44)*Inputs!$D$28*(1-Inputs!$D$38*MIN(1,MAX(0,(IF(H26>=1,999,H26/(Inputs!$D$34*(1-H26))*60)-Inputs!$D$36)/(Inputs!$D$37-Inputs!$D$36))))*Inputs!$D$13)*(1-Inputs!$D$19) -> 130502.74 | L26: =IF(AND(MAX(F26,G26,H26)<=Inputs!$D$35,E26<=Inputs!$D$8),"Yes","No") -> No
A27: Equal space per category | B27: 40 | C27: 40 | D27: 20 | E27: =B27*Inputs!$D$20+C27*Inputs!$D$21+D27*Inputs!$D$22 -> 120 | F27: =(Inputs!$D$6*Inputs!$D$14*Inputs!$D$26*(1+Inputs!$D$41*(D27-Inputs!$D$42))*Inputs!$D$29/(B27*Inputs!$D$32)) -> 0.85665682 | G27: =(Inputs!$D$6*MIN(Inputs!$E$15,Inputs!$D$15*(C27/Inputs!$D$43)^Inputs!$D$44)*Inputs!$D$27*Inputs!$D$30/(C27*Inputs!$D$33)) -> 0.33367114 | H27: =(Inputs!$D$6*MIN(Inputs!$E$16,Inputs!$D$16*(D27/Inputs!$D$42)^Inputs!$D$44)*Inputs!$D$28*Inputs!$D$31/(D27*Inputs!$D$34)) -> 0.963456 | I27: =MAX(IF(F27>=1,999,F27/(Inputs!$D$32*(1-F27))*60),IF(G27>=1,999,G27/(Inputs!$D$33*(1-G27))*60),IF(H27>=1,999,H27/(Inputs!$D$34*(1-H27))*60)) -> 45.195897 | J27: =(Inputs!$D$6*Inputs!$D$14*Inputs!$D$26*(1+Inputs!$D$41*(D27-Inputs!$D$42))*(1-Inputs!$D$38*MIN(1,MAX(0,(IF(F27>=1,999,F27/(Inputs!$D$32*(1-F27))*60)-Inputs!$D$36)/(Inputs!$D$37-Inputs!$D$36))))*Inputs!$D$11)+(Inputs!$D$6*MIN(Inputs!$E$15,Inputs!$D$15*(C27/Inputs!$D$43)^Inputs!$D$44)*Inputs!$D$27*(1-Inputs!$D$38*MIN(1,MAX(0,(IF(G27>=1,999,G27/(Inputs!$D$33*(1-G27))*60)-Inputs!$D$36)/(Inputs!$D$37-Inputs!$D$36))))*Inputs!$D$12)+(Inputs!$D$6*MIN(Inputs!$E$16,Inputs!$D$16*(D27/Inputs!$D$42)^Inputs!$D$44)*Inputs!$D$28*(1-Inputs!$D$38*MIN(1,MAX(0,(IF(H27>=1,999,H27/(Inputs!$D$34*(1-H27))*60)-Inputs!$D$36)/(Inputs!$D$37-Inputs!$D$36))))*Inputs!$D$13) -> 353254.29 | K27: =(Inputs!$D$6*Inputs!$D$14*Inputs!$D$26*(1+Inputs!$D$41*(D27-Inputs!$D$42))*(1-Inputs!$D$38*MIN(1,MAX(0,(IF(F27>=1,999,F27/(Inputs!$D$32*(1-F27))*60)-Inputs!$D$36)/(Inputs!$D$37-Inputs!$D$36))))*Inputs!$D$11)*(1-Inputs!$D$17)+(Inputs!$D$6*MIN(Inputs!$E$15,Inputs!$D$15*(C27/Inputs!$D$43)^Inputs!$D$44)*Inputs!$D$27*(1-Inputs!$D$38*MIN(1,MAX(0,(IF(G27>=1,999,G27/(Inputs!$D$33*(1-G27))*60)-Inputs!$D$36)/(Inputs!$D$37-Inputs!$D$36))))*Inputs!$D$12)*(1-Inputs!$D$18)+(Inputs!$D$6*MIN(Inputs!$E$16,Inputs!$D$16*(D27/Inputs!$D$42)^Inputs!$D$44)*Inputs!$D$28*(1-Inputs!$D$38*MIN(1,MAX(0,(IF(H27>=1,999,H27/(Inputs!$D$34*(1-H27))*60)-Inputs!$D$36)/(Inputs!$D$37-Inputs!$D$36))))*Inputs!$D$13)*(1-Inputs!$D$19) -> 136820.61 | L27: =IF(AND(MAX(F27,G27,H27)<=Inputs!$D$35,E27<=Inputs!$D$8),"Yes","No") -> No
A28: Proportional to participation | B28: 52 | C28: 22 | D28: 23 | E28: =B28*Inputs!$D$20+C28*Inputs!$D$21+D28*Inputs!$D$22 -> 120 | F28: =(Inputs!$D$6*Inputs!$D$14*Inputs!$D$26*(1+Inputs!$D$41*(D28-Inputs!$D$42))*Inputs!$D$29/(B28*Inputs!$D$32)) -> 0.67873579 | G28: =(Inputs!$D$6*MIN(Inputs!$E$15,Inputs!$D$15*(C28/Inputs!$D$43)^Inputs!$D$44)*Inputs!$D$27*Inputs!$D$30/(C28*Inputs!$D$33)) -> 0.50706631 | H28: =(Inputs!$D$6*MIN(Inputs!$E$16,Inputs!$D$16*(D28/Inputs!$D$42)^Inputs!$D$44)*Inputs!$D$28*Inputs!$D$31/(D28*Inputs!$D$34)) -> 0.8736619 | I28: =MAX(IF(F28>=1,999,F28/(Inputs!$D$32*(1-F28))*60),IF(G28>=1,999,G28/(Inputs!$D$33*(1-G28))*60),IF(H28>=1,999,H28/(Inputs!$D$34*(1-H28))*60)) -> 11.854746 | J28: =(Inputs!$D$6*Inputs!$D$14*Inputs!$D$26*(1+Inputs!$D$41*(D28-Inputs!$D$42))*(1-Inputs!$D$38*MIN(1,MAX(0,(IF(F28>=1,999,F28/(Inputs!$D$32*(1-F28))*60)-Inputs!$D$36)/(Inputs!$D$37-Inputs!$D$36))))*Inputs!$D$11)+(Inputs!$D$6*MIN(Inputs!$E$15,Inputs!$D$15*(C28/Inputs!$D$43)^Inputs!$D$44)*Inputs!$D$27*(1-Inputs!$D$38*MIN(1,MAX(0,(IF(G28>=1,999,G28/(Inputs!$D$33*(1-G28))*60)-Inputs!$D$36)/(Inputs!$D$37-Inputs!$D$36))))*Inputs!$D$12)+(Inputs!$D$6*MIN(Inputs!$E$16,Inputs!$D$16*(D28/Inputs!$D$42)^Inputs!$D$44)*Inputs!$D$28*(1-Inputs!$D$38*MIN(1,MAX(0,(IF(H28>=1,999,H28/(Inputs!$D$34*(1-H28))*60)-Inputs!$D$36)/(Inputs!$D$37-Inputs!$D$36))))*Inputs!$D$13) -> 374260.63 | K28: =(Inputs!$D$6*Inputs!$D$14*Inputs!$D$26*(1+Inputs!$D$41*(D28-Inputs!$D$42))*(1-Inputs!$D$38*MIN(1,MAX(0,(IF(F28>=1,999,F28/(Inputs!$D$32*(1-F28))*60)-Inputs!$D$36)/(Inputs!$D$37-Inputs!$D$36))))*Inputs!$D$11)*(1-Inputs!$D$17)+(Inputs!$D$6*MIN(Inputs!$E$15,Inputs!$D$15*(C28/Inputs!$D$43)^Inputs!$D$44)*Inputs!$D$27*(1-Inputs!$D$38*MIN(1,MAX(0,(IF(G28>=1,999,G28/(Inputs!$D$33*(1-G28))*60)-Inputs!$D$36)/(Inputs!$D$37-Inputs!$D$36))))*Inputs!$D$12)*(1-Inputs!$D$18)+(Inputs!$D$6*MIN(Inputs!$E$16,Inputs!$D$16*(D28/Inputs!$D$42)^Inputs!$D$44)*Inputs!$D$28*(1-Inputs!$D$38*MIN(1,MAX(0,(IF(H28>=1,999,H28/(Inputs!$D$34*(1-H28))*60)-Inputs!$D$36)/(Inputs!$D$37-Inputs!$D$36))))*Inputs!$D$13)*(1-Inputs!$D$19) -> 146072.9 | L28: =IF(AND(MAX(F28,G28,H28)<=Inputs!$D$35,E28<=Inputs!$D$8),"Yes","No") -> No
A29: Queueing minimums only (slack unused) | B29: =Demand!C13 -> 41 | C29: =Demand!C22 -> 14 | D29: =Demand!C31 -> 23 | E29: =B29*Inputs!$D$20+C29*Inputs!$D$21+D29*Inputs!$D$22 -> 101 | F29: =(Inputs!$D$6*Inputs!$D$14*Inputs!$D$26*(1+Inputs!$D$41*(D29-Inputs!$D$42))*Inputs!$D$29/(B29*Inputs!$D$32)) -> 0.86083563 | G29: =(Inputs!$D$6*MIN(Inputs!$E$15,Inputs!$D$15*(C29/Inputs!$D$43)^Inputs!$D$44)*Inputs!$D$27*Inputs!$D$30/(C29*Inputs!$D$33)) -> 0.69577851 | H29: =(Inputs!$D$6*MIN(Inputs!$E$16,Inputs!$D$16*(D29/Inputs!$D$42)^Inputs!$D$44)*Inputs!$D$28*Inputs!$D$31/(D29*Inputs!$D$34)) -> 0.8736619 | I29: =MAX(IF(F29>=1,999,F29/(Inputs!$D$32*(1-F29))*60),IF(G29>=1,999,G29/(Inputs!$D$33*(1-G29))*60),IF(H29>=1,999,H29/(Inputs!$D$34*(1-H29))*60)) -> 11.854746 | J29: =(Inputs!$D$6*Inputs!$D$14*Inputs!$D$26*(1+Inputs!$D$41*(D29-Inputs!$D$42))*(1-Inputs!$D$38*MIN(1,MAX(0,(IF(F29>=1,999,F29/(Inputs!$D$32*(1-F29))*60)-Inputs!$D$36)/(Inputs!$D$37-Inputs!$D$36))))*Inputs!$D$11)+(Inputs!$D$6*MIN(Inputs!$E$15,Inputs!$D$15*(C29/Inputs!$D$43)^Inputs!$D$44)*Inputs!$D$27*(1-Inputs!$D$38*MIN(1,MAX(0,(IF(G29>=1,999,G29/(Inputs!$D$33*(1-G29))*60)-Inputs!$D$36)/(Inputs!$D$37-Inputs!$D$36))))*Inputs!$D$12)+(Inputs!$D$6*MIN(Inputs!$E$16,Inputs!$D$16*(D29/Inputs!$D$42)^Inputs!$D$44)*Inputs!$D$28*(1-Inputs!$D$38*MIN(1,MAX(0,(IF(H29>=1,999,H29/(Inputs!$D$34*(1-H29))*60)-Inputs!$D$36)/(Inputs!$D$37-Inputs!$D$36))))*Inputs!$D$13) -> 352124.85 | K29: =(Inputs!$D$6*Inputs!$D$14*Inputs!$D$26*(1+Inputs!$D$41*(D29-Inputs!$D$42))*(1-Inputs!$D$38*MIN(1,MAX(0,(IF(F29>=1,999,F29/(Inputs!$D$32*(1-F29))*60)-Inputs!$D$36)/(Inputs!$D$37-Inputs!$D$36))))*Inputs!$D$11)*(1-Inputs!$D$17)+(Inputs!$D$6*MIN(Inputs!$E$15,Inputs!$D$15*(C29/Inputs!$D$43)^Inputs!$D$44)*Inputs!$D$27*(1-Inputs!$D$38*MIN(1,MAX(0,(IF(G29>=1,999,G29/(Inputs!$D$33*(1-G29))*60)-Inputs!$D$36)/(Inputs!$D$37-Inputs!$D$36))))*Inputs!$D$12)*(1-Inputs!$D$18)+(Inputs!$D$6*MIN(Inputs!$E$16,Inputs!$D$16*(D29/Inputs!$D$42)^Inputs!$D$44)*Inputs!$D$28*(1-Inputs!$D$38*MIN(1,MAX(0,(IF(H29>=1,999,H29/(Inputs!$D$34*(1-H29))*60)-Inputs!$D$36)/(Inputs!$D$37-Inputs!$D$36))))*Inputs!$D$13)*(1-Inputs!$D$19) -> 137570.95 | L29: =IF(AND(MAX(F29,G29,H29)<=Inputs!$D$35,E29<=Inputs!$D$8),"Yes","No") -> No
A32: Stress test: recommended mix under Low / Expected / High design days
A33: Scenario | B33: F | C33: M | D33: A | E33: Spaces | F33: F rho | G33: M rho | H33: A rho | I33: Max wait (min) | J33: Gross sales ($) | K33: Contribution ($) | L33: Within service level?
A34: Low design day | B34: =B8 -> 45 | C34: =B9 -> 21 | D34: =B10 -> 27 | E34: =B34*Inputs!$D$20+C34*Inputs!$D$21+D34*Inputs!$D$22 -> 120 | F34: =(Inputs!$C$6*Inputs!$D$14*Inputs!$D$26*(1+Inputs!$D$41*(D34-Inputs!$D$42))*Inputs!$D$29/(B34*Inputs!$D$32)) -> 0.6949115 | G34: =(Inputs!$C$6*MIN(Inputs!$E$15,Inputs!$D$15*(C34/Inputs!$D$43)^Inputs!$D$44)*Inputs!$D$27*Inputs!$D$30/(C34*Inputs!$D$33)) -> 0.44678491 | H34: =(Inputs!$C$6*MIN(Inputs!$E$16,Inputs!$D$16*(D34/Inputs!$D$42)^Inputs!$D$44)*Inputs!$D$28*Inputs!$D$31/(D34*Inputs!$D$34)) -> 0.6660236 | I34: =MAX(IF(F34>=1,999,F34/(Inputs!$D$32*(1-F34))*60),IF(G34>=1,999,G34/(Inputs!$D$33*(1-G34))*60),IF(H34>=1,999,H34/(Inputs!$D$34*(1-H34))*60)) -> 3.4186689 | J34: =(Inputs!$C$6*Inputs!$D$14*Inputs!$D$26*(1+Inputs!$D$41*(D34-Inputs!$D$42))*(1-Inputs!$D$38*MIN(1,MAX(0,(IF(F34>=1,999,F34/(Inputs!$D$32*(1-F34))*60)-Inputs!$D$36)/(Inputs!$D$37-Inputs!$D$36))))*Inputs!$D$11)+(Inputs!$C$6*MIN(Inputs!$E$15,Inputs!$D$15*(C34/Inputs!$D$43)^Inputs!$D$44)*Inputs!$D$27*(1-Inputs!$D$38*MIN(1,MAX(0,(IF(G34>=1,999,G34/(Inputs!$D$33*(1-G34))*60)-Inputs!$D$36)/(Inputs!$D$37-Inputs!$D$36))))*Inputs!$D$12)+(Inputs!$C$6*MIN(Inputs!$E$16,Inputs!$D$16*(D34/Inputs!$D$42)^Inputs!$D$44)*Inputs!$D$28*(1-Inputs!$D$38*MIN(1,MAX(0,(IF(H34>=1,999,H34/(Inputs!$D$34*(1-H34))*60)-Inputs!$D$36)/(Inputs!$D$37-Inputs!$D$36))))*Inputs!$D$13) -> 337712.34 | K34: =(Inputs!$C$6*Inputs!$D$14*Inputs!$D$26*(1+Inputs!$D$41*(D34-Inputs!$D$42))*(1-Inputs!$D$38*MIN(1,MAX(0,(IF(F34>=1,999,F34/(Inputs!$D$32*(1-F34))*60)-Inputs!$D$36)/(Inputs!$D$37-Inputs!$D$36))))*Inputs!$D$11)*(1-Inputs!$D$17)+(Inputs!$C$6*MIN(Inputs!$E$15,Inputs!$D$15*(C34/Inputs!$D$43)^Inputs!$D$44)*Inputs!$D$27*(1-Inputs!$D$38*MIN(1,MAX(0,(IF(G34>=1,999,G34/(Inputs!$D$33*(1-G34))*60)-Inputs!$D$36)/(Inputs!$D$37-Inputs!$D$36))))*Inputs!$D$12)*(1-Inputs!$D$18)+(Inputs!$C$6*MIN(Inputs!$E$16,Inputs!$D$16*(D34/Inputs!$D$42)^Inputs!$D$44)*Inputs!$D$28*(1-Inputs!$D$38*MIN(1,MAX(0,(IF(H34>=1,999,H34/(Inputs!$D$34*(1-H34))*60)-Inputs!$D$36)/(Inputs!$D$37-Inputs!$D$36))))*Inputs!$D$13)*(1-Inputs!$D$19) -> 133491.45 | L34: =IF(AND(MAX(F34,G34,H34)<=Inputs!$D$35,E34<=Inputs!$D$8),"Yes","No") -> Yes
