Workbook

Sheet README
A1: Autumn Harvest Festival: Growth Option Evaluation (Part 3)
A2: WDPR 2026 IE Case Study, Part 3. Built in 2026. Uses outputs of Parts 1 and 2.
A4: Question | B4: Which of three options should the festival pursue to accommodate future growth: A) extend hours from 10 to 12 per day, B) add Friday operations to each weekend, C) add a fifth weekend.
A5: Method | B5: Each option is evaluated on the same four lenses the case names. Operational: capacity added and the change in peak-hour F&B utilization (the binding constraint from Part 2). Financial: incremental net-new visits after cannibalization, incremental festival revenue and cost, break-even visits and cushion, 5-year NPV, IRR and payback under Low / Expected / High demand. Guest experience: peak-hour wait, weather exposure, fatigue. Feasibility: vendor booth-day economics and staffing load. A weighted decision matrix combines the lenses and is tested against alternative weight sets. The recommendation is phased using a real-options view: do the cheap, reversible option first, keep the scalable option in reserve, and decline the one whose downside lands on vendors.
A6: Revenue metric | B6: The case does not give admission price, the festival's share of vendor sales, or any costs. Festival net revenue per visit = admission + commission x vendor sales per visit - variable cost per visit, each an explicit input. Costs are built bottom-up per operating day and per operating hour. Every number is a blue cell; leadership should replace the admission price and daily cost with actuals.
A7: Sheet guide | B7: Inputs: every parameter with rationale. Options: per-option demand, revenue, cost, break-even, capacity relief, vendor Friday economics, under three scenarios. NPV: 5-year cash flows per option. Decision: weighted scoring matrix with weight sensitivity. Summary: dashboard and charts.
A8: Color legend | B8: Blue = editable input. Black = formula. Green = link. Yellow fill = key assumption.

Sheet Summary
A1: Summary dashboard: growth option recommendation
A2: Recommendation: pursue Option A (extend to 12 hours) now; hold Option C (fifth weekend) as the phase-two growth move once evenings are proven; do not pursue Option B (Fridays) in full-day form.
A4: Expected scenario | B4: Option A | C4: Option B | D4: Option C
A5: Capacity added (% of hours) | B5: =Options!C13 -> 0.2 | C5: =Options!C29 -> 0.5 | D5: =Options!C48 -> 0.25
A6: Net-new visits per season | B6: =Options!C16 -> 5439.84 | C6: =Options!C32 -> 9546.9192 | D6: =Options!C51 -> 7139.79
A7: Incremental festival revenue | B7: =Options!C17 -> 87176.421 | C7: =Options!C33 -> 133400.31 | D7: =Options!C53 -> 87294.54
A8: Incremental annual cost | B8: =Options!C19 -> 32000 | C8: =Options!C35 -> 97200 | D8: =Options!C55 -> 84000
A9: Annual net benefit (year 1) | B9: =Options!C20 -> 55176.421 | C9: =Options!C36 -> 36200.309 | D9: =Options!C56 -> 3294.5395
A10: Break-even cushion | B10: =Options!C22 -> 2.3753616 | C10: =Options!C38 -> 1.3724312 | D10: =Options!C58 -> 1.0392207
A11: F&B peak utilization after, expected day (from 82%) | B11: =Options!C24 -> 0.76284 | C11: =Options!C40 -> 0.738716 | D11: =Options!C60 -> 0.778325
A12: F&B peak utilization after, High day (from 102%) | B12: =Options!C25 -> 0.952848 | C12: =Options!C41 -> 0.9227152 | D12: =Options!C61 -> 0.97219
A13: 5-year NPV, Expected | B13: =NPV!H6 -> 204734.33 | C13: =NPV!H7 -> 143291.42 | D13: =NPV!H8 -> 5783.8885
A14: 5-year NPV, Low | B14: =NPV!H12 -> 17341.548 | C14: =NPV!H13 -> -58498.966 | D14: =NPV!H14 -> -126870.83
A15: 5-year NPV, High | B15: =NPV!H18 -> 392127.1 | C15: =NPV!H19 -> 461907.83 | D15: =NPV!H20 -> 174589.31
A16: Payback (years), Expected | B16: =NPV!J6 -> 0.63432892 | C16: =NPV!J7 -> 0.55248148 | D16: =NPV!J8 -> 4.5529883
A17: Weighted decision score (of 5) | B17: =Decision!C10 -> 4.35 | C17: =Decision!D10 -> 2.75 | D17: =Decision!E10 -> 2.45
A18: F&B vendor Friday profit per booth-day (Option B feasibility) | C18: =Options!C43 -> -37.885151
A21: Annual net benefit (year 1) | B21: Low | C21: Expected | D21: High
A22: Option A | B22: =Options!B20 -> 11588.211 | C22: =Options!C20 -> 55176.421 | D22: =Options!D20 -> 98764.632
A23: Option B | B23: =Options!B36 -> -10736.837 | C23: =Options!C36 -> 36200.309 | D23: =Options!D36 -> 110311.59
A24: Option C | B24: =Options!B56 -> -27561.408 | C24: =Options!C56 -> 3294.5395 | D24: =Options!D56 -> 42559.267
A27: 5-year NPV | B27: Low | C27: Expected | D27: High
A28: Option A | B28: =NPV!H12 -> 17341.548 | C28: =NPV!H6 -> 204734.33 | D28: =NPV!H18 -> 392127.1
A29: Option B | B29: =NPV!H13 -> -58498.966 | C29: =NPV!H7 -> 143291.42 | D29: =NPV!H19 -> 461907.83
A30: Option C | B30: =NPV!H14 -> -126870.83 | C30: =NPV!H8 -> 5783.8885 | D30: =NPV!H20 -> 174589.31

Sheet Inputs
A1: Inputs and assumptions
A2: Columns C/D/E = Low / Expected / High where an input varies by scenario; single-value inputs in column D.
A4: Parameter | B4: Key | C4: Low | D4: Expected | E4: High | F4: Source / rationale
A5: Baseline from Parts 1 and 2 (2026 expected)
A6: Season attendance (visits) | B6: V | D6: 67998 | F6: Part 1 expected forecast.
A7: Operating days | B7: days | D7: 8 | F7: Case: 4 weekends x 2 days.
A8: Operating hours per day | B8: hrs | D8: 10 | F8: Case: 10 AM to 8 PM.
A9: Saturday share of a weekend | B9: sat_share | D9: 0.52 | F9: Part 2 assumption.
A10: Weekend 1 share of season (proxy for a shoulder weekend) | B10: w1_share | D10: 0.2 | F10: Case seasonal index. Used to size a fifth weekend.
A11: Vendor gross sales per visit ($) | B11: vend_visit | D11: =394357/10808 -> 36.487509 | F11: Part 2: $394,357 gross sales / 10,808 guests on the expected design day.
A12: F&B peak-hour share of daily transactions (10-hour day) | B12: peak_share | D12: 0.15 | F12: Part 2 assumption.
A13: F&B peak-hour utilization, expected design day (Part 2) | B13: rho_exp | D13: 0.815 | F13: Part 2 result with the recommended 45/21/27 mix.
A14: F&B peak-hour utilization, High design day (Part 2) | B14: rho_high | D14: 1.018 | F14: Part 2 stress test: the mix cannot absorb a High Saturday.
A15: F&B booth sales on the expected design day ($/booth) | B15: fb_booth_sales | D15: =289041/45 -> 6423.1333 | F15: Part 2: $289,041 F&B sales / 45 booths.
A16: Merchandise booth sales on the expected design day ($/booth) | B16: m_booth_sales | D16: =58671/21 -> 2793.8571 | F16: Part 2.
A18: Festival economics per visit
A19: Average admission revenue per visit ($) | B19: adm | D19: 10 | F19: Team assumption. The case confirms admission is charged (concert 'free with general festival admission') but not the price. Blend of adult, child, free-under-5, and pass holders. Leadership should replace with the actual gate yield.
A20: Festival share of vendor gross sales | B20: comm | D20: 0.15 | F20: Cal Poly Pomona Pumpkin Festival (a five-weekend fall harvest festival) charges vendors 15% of gross sales; other festivals range 10 to 20% or a flat fee, whichever is greater.
A21: Variable festival cost per visit ($) | B21: varc | D21: 1.5 | F21: Team assumption: waste, restroom consumables, ticketing fees, insurance loading per guest.
A22: Festival net revenue per visit ($) | B22: netrev | D22: =D19+D20*D11-D21 -> 13.973126 | F22: Formula: admission + commission x vendor sales per visit - variable cost.
A24: Festival operating cost structure (bottom-up, team assumptions)
A25: Security, gate, and operations staff per day | B25: c_staff | D25: 11000 | F25: 40 staff x 11 paid hours x $25 loaded rate for a 10-hour day.
A26: Entertainment and stage per day | B26: c_ent | D26: 5000 | F26: Performers, sound, stage crew.
A27: Sanitation, utilities, waste per day | B27: c_util | D27: 4000 | F27: Portable restrooms, power, water, hauling.
A28: Medical, permits, insurance per day | B28: c_med | D28: 2500 | F28: First aid post, daily permit and insurance loading.
A29: Parking and traffic control per day | B29: c_park | D29: 3000 | F29: Lot attendants, signage, police detail.
A30: Marketing per operating day | B30: c_mkt | D30: 1500 | F30: Season marketing spread across days.
A31: Total festival cost per operating day | B31: cost_day | D31: =SUM(D25:D30) -> 27000 | F31: Formula.
A32: Incremental cost per added operating hour | B32: cost_hr | D32: 2000 | F32: Staff and utilities scale with hours (~$1,500/hr) plus evening lighting and power (~$500/hr). Entertainment, permits, parking do not scale with hours.
A33: Friday cost as a fraction of a full weekend day | B33: fri_cost_fac | D33: 0.9 | F33: Lighter staffing for a lighter crowd; most day costs are fixed.
A34: Fixed cost of adding a fifth weekend (beyond daily costs) | B34: wk_fixed | D34: 30000 | F34: Extra site rental, vendor re-setup, weekend-specific marketing.
A35: One-time cost, Option A (lighting, generators, marketing of new hours) | B35: capex_A | D35: 35000 | F35: Team assumption.
A36: One-time cost, Option B (permits, Friday marketing, scheduling) | B36: capex_B | D36: 20000 | F36: Team assumption.
A37: One-time cost, Option C (site agreement, marketing, contracts) | B37: capex_C | D37: 15000 | F37: Team assumption.
A39: Option A: extend hours 10 to 12 per day
A40: Hours added per day | B40: A_hrs | D40: 2 | F40: Case: 8 PM to 10 PM.
A41: Net-new visits from evening hours (% of season attendance) | B41: A_new | C41: 0.04 | D41: 0.08 | E41: 0.12 | F41: Team judgment: guests who cannot arrive before evening (Saturday workers, dinner-and-lights visitors). Concert and lighting make evenings a draw. No cannibalization: extra hours on the same day cannot shift a visit from another day.
A42: Uplift in vendor sales from existing guests staying later (% of vendor sales) | B42: A_dwell | C42: 0.015 | D42: 0.03 | E42: 0.045 | F42: Team judgment: dinner-hour F&B spend by guests who would otherwise leave at 8 PM.
A43: Share of demand that redistributes across the longer day | B43: A_spread | D43: 0.8 | F43: Team judgment: peak-hour share falls toward 15% x 10/12 as demand spreads; 80% of that theoretical spread is realized.
A45: Option B: add Friday operations
...

Sheet Options
A1: Option evaluation under Low / Expected / High demand
A2: All revenue and cost figures are annual increments over the 2026 baseline, in year-1 dollars. Scenario columns vary the demand-response inputs; cost inputs are held at Expected.
A3: Metric | B3: Low | C3: Expected | D3: High | E3: Logic
A4: Baseline
A5: Season visits | B5: =Inputs!$D$6 -> 67998 | C5: =Inputs!$D$6 -> 67998 | D5: =Inputs!$D$6 -> 67998 | E5: Part 1.
A6: Average visits per day | B6: =Inputs!$D$6/Inputs!$D$7 -> 8499.75 | C6: =Inputs!$D$6/Inputs!$D$7 -> 8499.75 | D6: =Inputs!$D$6/Inputs!$D$7 -> 8499.75 | E6: V / 8.
A7: Average Saturday visits | B7: =Inputs!$D$6/4*Inputs!$D$9 -> 8839.74 | C7: =Inputs!$D$6/4*Inputs!$D$9 -> 8839.74 | D7: =Inputs!$D$6/4*Inputs!$D$9 -> 8839.74 | E7: Weekend average x Saturday share.
A8: Festival net revenue per visit | B8: =Inputs!$D$22 -> 13.973126 | C8: =Inputs!$D$22 -> 13.973126 | D8: =Inputs!$D$22 -> 13.973126 | E8: Inputs.
A9: Baseline festival operating cost (8 days) | B9: =Inputs!$D$31*Inputs!$D$7 -> 216000 | C9: =Inputs!$D$31*Inputs!$D$7 -> 216000 | D9: =Inputs!$D$31*Inputs!$D$7 -> 216000 | E9: Cost per day x days.
A11: Option A: extend hours to 12 per day
A12: Operating hours added per season | B12: =Inputs!$D$40*Inputs!$D$7 -> 16 | C12: =Inputs!$D$40*Inputs!$D$7 -> 16 | D12: =Inputs!$D$40*Inputs!$D$7 -> 16 | E12: 2 hours x 8 days.
A13: Capacity added (% of operating hours) | B13: =B12/(Inputs!$D$8*Inputs!$D$7) -> 0.2 | C13: =B12/(Inputs!$D$8*Inputs!$D$7) -> 0.2 | D13: =B12/(Inputs!$D$8*Inputs!$D$7) -> 0.2 | E13: 16 / 80.
A14: Gross new visits | B14: =Inputs!$D$6*Inputs!$C$41 -> 2719.92 | C14: =Inputs!$D$6*Inputs!$D$41 -> 5439.84 | D14: =Inputs!$D$6*Inputs!$E$41 -> 8159.76 | E14: V x evening uplift %.
A15: Visits shifted from other days (cannibalized) | B15: =0 -> 0 | C15: =0 -> 0 | D15: =0 -> 0 | E15: None: same days, more hours.
A16: Net-new visits | B16: =B14-B15 -> 2719.92 | C16: =C14-C15 -> 5439.84 | D16: =D14-D15 -> 8159.76 | E16: Gross minus shifted.
A17: Incremental festival revenue | B17: =B16*Inputs!$D$22+Inputs!$D$20*Inputs!$C$42*Inputs!$D$6*Inputs!$D$11 -> 43588.211 | C17: =C16*Inputs!$D$22+Inputs!$D$20*Inputs!$D$42*Inputs!$D$6*Inputs!$D$11 -> 87176.421 | D17: =D16*Inputs!$D$22+Inputs!$D$20*Inputs!$E$42*Inputs!$D$6*Inputs!$D$11 -> 130764.63 | E17: Net-new visits x net revenue per visit + commission on dwell-driven vendor sales.
A18: Incremental vendor gross sales (ecosystem view) | B18: =B16*Inputs!$D$11+Inputs!$C$42*Inputs!$D$6*Inputs!$D$11 -> 136459.27 | C18: =C16*Inputs!$D$11+Inputs!$D$42*Inputs!$D$6*Inputs!$D$11 -> 272918.54 | D18: =D16*Inputs!$D$11+Inputs!$E$42*Inputs!$D$6*Inputs!$D$11 -> 409377.81 | E18: For vendor buy-in.
A19: Incremental annual operating cost | B19: =Inputs!$D$32*B12 -> 32000 | C19: =Inputs!$D$32*B12 -> 32000 | D19: =Inputs!$D$32*B12 -> 32000 | E19: Cost per hour x hours added.
A20: Annual net benefit (year 1) | B20: =B17-B19 -> 11588.211 | C20: =C17-C19 -> 55176.421 | D20: =D17-D19 -> 98764.632 | E20: Revenue minus cost.
A21: Break-even net-new visits | B21: =B19/Inputs!$D$22 -> 2290.1103 | C21: =C19/Inputs!$D$22 -> 2290.1103 | D21: =D19/Inputs!$D$22 -> 2290.1103 | E21: Cost / net revenue per visit.
A22: Break-even cushion (net-new / break-even) | B22: =B16/B21 -> 1.1876808 | C22: =C16/C21 -> 2.3753616 | D22: =D16/D21 -> 3.5630424 | E22: Above 1.0 = profitable; 2.0 = demand could halve.
A23: F&B peak-hour share after extension | B23: =Inputs!$D$12*(1-Inputs!$D$43*(1-Inputs!$D$8/(Inputs!$D$8+Inputs!$D$40))) -> 0.13 | C23: =Inputs!$D$12*(1-Inputs!$D$43*(1-Inputs!$D$8/(Inputs!$D$8+Inputs!$D$40))) -> 0.13 | D23: =Inputs!$D$12*(1-Inputs!$D$43*(1-Inputs!$D$8/(Inputs!$D$8+Inputs!$D$40))) -> 0.13 | E23: 15% x (1 - spread x (1 - 10/12)).
A24: F&B peak utilization after, expected day | B24: =Inputs!$D$13*B23/Inputs!$D$12*(1+Inputs!$C$41) -> 0.73458667 | C24: =Inputs!$D$13*C23/Inputs!$D$12*(1+Inputs!$D$41) -> 0.76284 | D24: =Inputs!$D$13*D23/Inputs!$D$12*(1+Inputs!$E$41) -> 0.79109333 | E24: Part 2 utilization x share ratio x (1 + new visits).
A25: F&B peak utilization after, High day | B25: =Inputs!$D$14*B23/Inputs!$D$12*(1+Inputs!$C$41) -> 0.91755733 | C25: =Inputs!$D$14*C23/Inputs!$D$12*(1+Inputs!$D$41) -> 0.952848 | D25: =Inputs!$D$14*D23/Inputs!$D$12*(1+Inputs!$E$41) -> 0.98813867 | E25: Same, High design day.
A27: Option B: add Friday operations
A28: Operating days added | B28: =Inputs!$D$46 -> 4 | C28: =Inputs!$D$46 -> 4 | D28: =Inputs!$D$46 -> 4 | E28: 4 Fridays.
A29: Capacity added (% of operating hours) | B29: =B28/Inputs!$D$7 -> 0.5 | C29: =B28/Inputs!$D$7 -> 0.5 | D29: =B28/Inputs!$D$7 -> 0.5 | E29: 4 / 8.
A30: Gross Friday visits | B30: =Inputs!$D$46*Inputs!$C$47*B7 -> 12375.636 | C30: =Inputs!$D$46*Inputs!$D$47*C7 -> 15911.532 | D30: =Inputs!$D$46*Inputs!$E$47*D7 -> 21215.376 | E30: 4 x Friday ratio x Saturday visits.
A31: Visits shifted from Saturday/Sunday | B31: =B30*Inputs!$C$48 -> 6187.818 | C31: =C30*Inputs!$D$48 -> 6364.6128 | D31: =D30*Inputs!$E$48 -> 6364.6128 | E31: Gross x cannibalization.
A32: Net-new visits | B32: =B30-B31 -> 6187.818 | C32: =C30-C31 -> 9546.9192 | D32: =D30-D31 -> 14850.763
A33: Incremental festival revenue | B33: =B32*Inputs!$D$22 -> 86463.163 | C33: =C32*Inputs!$D$22 -> 133400.31 | D33: =D32*Inputs!$D$22 -> 207511.59 | E33: Net-new x net revenue per visit.
A34: Incremental vendor gross sales (ecosystem view) | B34: =B32*Inputs!$D$11 -> 225778.07 | C34: =C32*Inputs!$D$11 -> 348343.3 | D34: =D32*Inputs!$D$11 -> 541867.36
A35: Incremental annual operating cost | B35: =Inputs!$D$46*Inputs!$D$31*Inputs!$D$33 -> 97200 | C35: =Inputs!$D$46*Inputs!$D$31*Inputs!$D$33 -> 97200 | D35: =Inputs!$D$46*Inputs!$D$31*Inputs!$D$33 -> 97200 | E35: 4 x day cost x Friday factor.
A36: Annual net benefit (year 1) | B36: =B33-B35 -> -10736.837 | C36: =C33-C35 -> 36200.309 | D36: =D33-D35 -> 110311.59
A37: Break-even net-new visits | B37: =B35/Inputs!$D$22 -> 6956.2099 | C37: =C35/Inputs!$D$22 -> 6956.2099 | D37: =D35/Inputs!$D$22 -> 6956.2099
A38: Break-even cushion | B38: =B32/B37 -> 0.88953871 | C38: =C32/C37 -> 1.3724312 | D38: =D32/D37 -> 2.1348929
A39: Saturday/Sunday load reduction from shifted visits | B39: =B31/Inputs!$D$7/B6 -> 0.091 | C39: =C31/Inputs!$D$7/C6 -> 0.0936 | D39: =D31/Inputs!$D$7/D6 -> 0.0936 | E39: Shifted visits per weekend day / average day.
A40: F&B peak utilization after, expected day | B40: =Inputs!$D$13*(1-B39) -> 0.740835 | C40: =Inputs!$D$13*(1-C39) -> 0.738716 | D40: =Inputs!$D$13*(1-D39) -> 0.738716
A41: F&B peak utilization after, High day | B41: =Inputs!$D$14*(1-B39) -> 0.925362 | C41: =Inputs!$D$14*(1-C39) -> 0.9227152 | D41: =Inputs!$D$14*(1-D39) -> 0.9227152
A42: F&B booth: Friday sales per booth-day | B42: =Inputs!$D$15*B6/10808*Inputs!$C$47 -> 1767.9737 | C42: =Inputs!$D$15*C6/10808*Inputs!$D$47 -> 2273.109 | D42: =Inputs!$D$15*D6/10808*Inputs!$E$47 -> 3030.812 | E42: Design-day booth sales scaled to an average day, then to Friday.
...

Sheet NPV
A1: Five-year discounted cash flow by option (Expected scenario; Low and High below)
A2: Year 0 = one-time cost. Years 1 to 5: incremental revenue grows at g_rev, incremental cost at g_cost. NPV at the discount rate; IRR; simple payback = capex / year-1 net benefit.
A4: Expected scenario
A5: Option | B5: Year 0 | C5: Year 1 | D5: Year 2 | E5: Year 3 | F5: Year 4 | G5: Year 5 | H5: NPV | I5: IRR | J5: Payback (yrs)
A6: Option A | B6: =-Inputs!$D$35 -> -35000 | C6: =Options!C17*(1+Inputs!$D$60)^0-Options!C19*(1+Inputs!$D$61)^0 -> 55176.421 | D6: =Options!C17*(1+Inputs!$D$60)^1-Options!C19*(1+Inputs!$D$61)^1 -> 57703.478 | E6: =Options!C17*(1+Inputs!$D$60)^2-Options!C19*(1+Inputs!$D$61)^2 -> 60341.217 | F6: =Options!C17*(1+Inputs!$D$60)^3-Options!C19*(1+Inputs!$D$61)^3 -> 63094.354 | G6: =Options!C17*(1+Inputs!$D$60)^4-Options!C19*(1+Inputs!$D$61)^4 -> 65967.801 | H6: =B6+NPV(Inputs!$D$59,C6:G6) -> 204734.33 | I6: =IFERROR(IRR(B6:G6),"n/a") -> 1.6058148 | J6: =IF(C6>0,-B6/C6,"never") -> 0.63432892
A7: Option B | B7: =-Inputs!$D$36 -> -20000 | C7: =Options!C33*(1+Inputs!$D$60)^0-Options!C35*(1+Inputs!$D$61)^0 -> 36200.309 | D7: =Options!C33*(1+Inputs!$D$60)^1-Options!C35*(1+Inputs!$D$61)^1 -> 38620.321 | E7: =Options!C33*(1+Inputs!$D$60)^2-Options!C35*(1+Inputs!$D$61)^2 -> 41166.294 | F7: =Options!C33*(1+Inputs!$D$60)^3-Options!C35*(1+Inputs!$D$61)^3 -> 43844.14 | G7: =Options!C33*(1+Inputs!$D$60)^4-Options!C35*(1+Inputs!$D$61)^4 -> 46660.037 | H7: =B7+NPV(Inputs!$D$59,C7:G7) -> 143291.42 | I7: =IFERROR(IRR(B7:G7),"n/a") -> 1.8634755 | J7: =IF(C7>0,-B7/C7,"never") -> 0.55248148
A8: Option C | B8: =-Inputs!$D$37 -> -15000 | C8: =Options!C53*(1+Inputs!$D$60)^0-Options!C55*(1+Inputs!$D$61)^0 -> 3294.5395 | D8: =Options!C53*(1+Inputs!$D$60)^1-Options!C55*(1+Inputs!$D$61)^1 -> 4266.3211 | E8: =Options!C53*(1+Inputs!$D$60)^2-Options!C55*(1+Inputs!$D$61)^2 -> 5302.174 | F8: =Options!C53*(1+Inputs!$D$60)^3-Options!C55*(1+Inputs!$D$61)^3 -> 6405.4169 | G8: =Options!C53*(1+Inputs!$D$60)^4-Options!C55*(1+Inputs!$D$61)^4 -> 7579.5243 | H8: =B8+NPV(Inputs!$D$59,C8:G8) -> 5783.8885 | I8: =IFERROR(IRR(B8:G8),"n/a") -> 0.1976781 | J8: =IF(C8>0,-B8/C8,"never") -> 4.5529883
A10: Low scenario
A11: Option | B11: Year 0 | C11: Year 1 | D11: Year 2 | E11: Year 3 | F11: Year 4 | G11: Year 5 | H11: NPV | I11: IRR | J11: Payback (yrs)
A12: Option A | B12: =-Inputs!$D$35 -> -35000 | C12: =Options!B17*(1+Inputs!$D$60)^0-Options!B19*(1+Inputs!$D$61)^0 -> 11588.211 | D12: =Options!B17*(1+Inputs!$D$60)^1-Options!B19*(1+Inputs!$D$61)^1 -> 12371.739 | E12: =Options!B17*(1+Inputs!$D$60)^2-Options!B19*(1+Inputs!$D$61)^2 -> 13196.209 | F12: =Options!B17*(1+Inputs!$D$60)^3-Options!B19*(1+Inputs!$D$61)^3 -> 14063.545 | G12: =Options!B17*(1+Inputs!$D$60)^4-Options!B19*(1+Inputs!$D$61)^4 -> 14975.759 | H12: =B12+NPV(Inputs!$D$59,C12:G12) -> 17341.548 | I12: =IFERROR(IRR(B12:G12),"n/a") -> 0.2448381 | J12: =IF(C12>0,-B12/C12,"never") -> 3.020311
A13: Option B | B13: =-Inputs!$D$36 -> -20000 | C13: =Options!B33*(1+Inputs!$D$60)^0-Options!B35*(1+Inputs!$D$61)^0 -> -10736.837 | D13: =Options!B33*(1+Inputs!$D$60)^1-Options!B35*(1+Inputs!$D$61)^1 -> -10194.311 | E13: =Options!B33*(1+Inputs!$D$60)^2-Options!B35*(1+Inputs!$D$61)^2 -> -9600.9229 | F13: =Options!B33*(1+Inputs!$D$60)^3-Options!B35*(1+Inputs!$D$61)^3 -> -8953.765 | G13: =Options!B33*(1+Inputs!$D$60)^4-Options!B35*(1+Inputs!$D$61)^4 -> -8249.785 | H13: =B13+NPV(Inputs!$D$59,C13:G13) -> -58498.966 | I13: =IFERROR(IRR(B13:G13),"n/a") -> n/a | J13: =IF(C13>0,-B13/C13,"never") -> never
A14: Option C | B14: =-Inputs!$D$37 -> -15000 | C14: =Options!B53*(1+Inputs!$D$60)^0-Options!B55*(1+Inputs!$D$61)^0 -> -27561.408 | D14: =Options!B53*(1+Inputs!$D$60)^1-Options!B55*(1+Inputs!$D$61)^1 -> -27823.864 | E14: =Options!B53*(1+Inputs!$D$60)^2-Options!B55*(1+Inputs!$D$61)^2 -> -28071.619 | F14: =Options!B53*(1+Inputs!$D$60)^3-Options!B55*(1+Inputs!$D$61)^3 -> -28303.328 | G14: =Options!B53*(1+Inputs!$D$60)^4-Options!B55*(1+Inputs!$D$61)^4 -> -28517.57 | H14: =B14+NPV(Inputs!$D$59,C14:G14) -> -126870.83 | I14: =IFERROR(IRR(B14:G14),"n/a") -> n/a | J14: =IF(C14>0,-B14/C14,"never") -> never
A16: High scenario
A17: Option | B17: Year 0 | C17: Year 1 | D17: Year 2 | E17: Year 3 | F17: Year 4 | G17: Year 5 | H17: NPV | I17: IRR | J17: Payback (yrs)
A18: Option A | B18: =-Inputs!$D$35 -> -35000 | C18: =Options!D17*(1+Inputs!$D$60)^0-Options!D19*(1+Inputs!$D$61)^0 -> 98764.632 | D18: =Options!D17*(1+Inputs!$D$60)^1-Options!D19*(1+Inputs!$D$61)^1 -> 103035.22 | E18: =Options!D17*(1+Inputs!$D$60)^2-Options!D19*(1+Inputs!$D$61)^2 -> 107486.23 | F18: =Options!D17*(1+Inputs!$D$60)^3-Options!D19*(1+Inputs!$D$61)^3 -> 112125.16 | G18: =Options!D17*(1+Inputs!$D$60)^4-Options!D19*(1+Inputs!$D$61)^4 -> 116959.84 | H18: =B18+NPV(Inputs!$D$59,C18:G18) -> 392127.1 | I18: =IFERROR(IRR(B18:G18),"n/a") -> 2.8610094 | J18: =IF(C18>0,-B18/C18,"never") -> 0.35437787
A19: Option B | B19: =-Inputs!$D$36 -> -20000 | C19: =Options!D33*(1+Inputs!$D$60)^0-Options!D35*(1+Inputs!$D$61)^0 -> 110311.59 | D19: =Options!D33*(1+Inputs!$D$60)^1-Options!D35*(1+Inputs!$D$61)^1 -> 115696.05 | E19: =Options!D33*(1+Inputs!$D$60)^2-Options!D35*(1+Inputs!$D$61)^2 -> 121325.06 | F19: =Options!D33*(1+Inputs!$D$60)^3-Options!D35*(1+Inputs!$D$61)^3 -> 127209.25 | G19: =Options!D33*(1+Inputs!$D$60)^4-Options!D35*(1+Inputs!$D$61)^4 -> 133359.75 | H19: =B19+NPV(Inputs!$D$59,C19:G19) -> 461907.83 | I19: =IFERROR(IRR(B19:G19),"n/a") -> 5.5637875 | J19: =IF(C19>0,-B19/C19,"never") -> 0.18130461
A20: Option C | B20: =-Inputs!$D$37 -> -15000 | C20: =Options!D53*(1+Inputs!$D$60)^0-Options!D55*(1+Inputs!$D$61)^0 -> 42559.267 | D20: =Options!D53*(1+Inputs!$D$60)^1-Options!D55*(1+Inputs!$D$61)^1 -> 45101.638 | E20: =Options!D53*(1+Inputs!$D$60)^2-Options!D55*(1+Inputs!$D$61)^2 -> 47770.903 | F20: =Options!D53*(1+Inputs!$D$60)^3-Options!D55*(1+Inputs!$D$61)^3 -> 50572.895 | G20: =Options!D53*(1+Inputs!$D$60)^4-Options!D55*(1+Inputs!$D$61)^4 -> 53513.702 | H20: =B20+NPV(Inputs!$D$59,C20:G20) -> 174589.31 | I20: =IFERROR(IRR(B20:G20),"n/a") -> 2.8925997 | J20: =IF(C20>0,-B20/C20,"never") -> 0.35244968

Sheet Decision
A1: Weighted decision matrix (1 = poor, 5 = excellent) with weight sensitivity
A2: Scores are the team's assessment, each justified from the Options and NPV sheets. Weights are editable; the sensitivity block re-ranks under three alternative weight sets so leadership can see whether the answer depends on the weights.
A4: Criterion | B4: Weight | C4: Option A | D4: Option B | E4: Option C | F4: Case lens | G4: Basis for scores
A5: Financial return (Expected NPV, cushion) | B5: 0.3 | C5: 4 | D5: 3 | E5: 2 | F5: Financial | G5: A: highest expected NPV per dollar of cost, 2.4x cushion. B: higher upside but 1.4x cushion and negative in Low. C: roughly break-even after weather.
A6: Peak congestion relief (Part 2 constraint) | B6: 0.25 | C6: 5 | D6: 3 | E6: 2 | F6: Operational / guest experience | G6: A spreads the lunch peak structurally (share 15% to 13%) and adds evening dwell; B and C relieve only through speculative shifting.
A7: Risk and reversibility | B7: 0.2 | C7: 5 | D7: 2 | E7: 2 | F7: Financial / operational | G7: A: small, reversible, positive in all scenarios. B: demand uncertain, negative in Low, vendor churn risk. C: weather exposure, negative in Low.
A8: Vendor and staff feasibility | B8: 0.15 | C8: 4 | D8: 2 | E8: 3 | F8: Operational | G8: A: vendors staff 2 more hours at high dinner spend. B: F&B booth-days at or below break-even, 3-day weekends x 4. C: one more weekend to staff; vendors already contracted seasonally.
A9: Growth headroom (scalable capacity) | B9: 0.1 | C9: 3 | D9: 4 | E9: 5 | F9: Strategic | G9: A adds 20% once and is then exhausted. B adds 50% hours but on low-yield days. C adds 25% of proven high-yield days and can be repeated (sixth weekend).
A10: Weighted score | B10: =SUM(B5:B9) -> 1 | C10: =SUMPRODUCT($B$5:$B$9,C5:C9) -> 4.35 | D10: =SUMPRODUCT($B$5:$B$9,D5:D9) -> 2.75 | E10: =SUMPRODUCT($B$5:$B$9,E5:E9) -> 2.45
A11: Rank | C11: =RANK(C10,$C$10:$E$10) -> 1 | D11: =RANK(D10,$C$10:$E$10) -> 2 | E11: =RANK(E10,$C$10:$E$10) -> 3
A12: Check: weights sum to 100% | B12: =IF(ABS(B10-1)<0.001,"OK","ERROR") -> OK
A14: Weight sensitivity: does the ranking change under different priorities?
A15: Weight set | B15: Financial | C15: Congestion | D15: Risk | E15: Feasibility | F15: Growth | G15: Score A | H15: Score B | I15: Score C | J15: Top option
A16: Base | B16: 0.3 | C16: 0.25 | D16: 0.2 | E16: 0.15 | F16: 0.1 | G16: =SUMPRODUCT(B16:F16,TRANSPOSE(C$5:C$9)) -> 4.35 | H16: =SUMPRODUCT(B16:F16,TRANSPOSE(D$5:D$9)) -> 2.75 | I16: =SUMPRODUCT(B16:F16,TRANSPOSE(E$5:E$9)) -> 2.45 | J16: =INDEX({"A","B","C"},MATCH(MAX(G16:I16),G16:I16,0)) -> A
A17: Finance-heavy | B17: 0.5 | C17: 0.15 | D17: 0.15 | E17: 0.1 | F17: 0.1 | G17: =SUMPRODUCT(B17:F17,TRANSPOSE(C$5:C$9)) -> 4.2 | H17: =SUMPRODUCT(B17:F17,TRANSPOSE(D$5:D$9)) -> 2.85 | I17: =SUMPRODUCT(B17:F17,TRANSPOSE(E$5:E$9)) -> 2.4 | J17: =INDEX({"A","B","C"},MATCH(MAX(G17:I17),G17:I17,0)) -> A
A18: Growth-heavy | B18: 0.2 | C18: 0.15 | D18: 0.15 | E18: 0.1 | F18: 0.4 | G18: =SUMPRODUCT(B18:F18,TRANSPOSE(C$5:C$9)) -> 3.9 | H18: =SUMPRODUCT(B18:F18,TRANSPOSE(D$5:D$9)) -> 3.15 | I18: =SUMPRODUCT(B18:F18,TRANSPOSE(E$5:E$9)) -> 3.3 | J18: =INDEX({"A","B","C"},MATCH(MAX(G18:I18),G18:I18,0)) -> A
A19: Guest-experience-heavy | B19: 0.15 | C19: 0.45 | D19: 0.2 | E19: 0.15 | F19: 0.05 | G19: =SUMPRODUCT(B19:F19,TRANSPOSE(C$5:C$9)) -> 4.6 | H19: =SUMPRODUCT(B19:F19,TRANSPOSE(D$5:D$9)) -> 2.7 | I19: =SUMPRODUCT(B19:F19,TRANSPOSE(E$5:E$9)) -> 2.3 | J19: =INDEX({"A","B","C"},MATCH(MAX(G19:I19),G19:I19,0)) -> A
A20: Risk-averse | B20: 0.2 | C20: 0.2 | D20: 0.4 | E20: 0.15 | F20: 0.05 | G20: =SUMPRODUCT(B20:F20,TRANSPOSE(C$5:C$9)) -> 4.55 | H20: =SUMPRODUCT(B20:F20,TRANSPOSE(D$5:D$9)) -> 2.5 | I20: =SUMPRODUCT(B20:F20,TRANSPOSE(E$5:E$9)) -> 2.3 | J20: =INDEX({"A","B","C"},MATCH(MAX(G20:I20),G20:I20,0)) -> A
